Workbook

Sheet Presupuesto
B2: PRESUPUESTO | K2: CONFIGURADOR
B4: Número | C4: PRE-0001 | D4: Fecha | K4: Configuración | L4: FRA MUSE MICR — MUSELINA DAMA [#1]
B5: Cliente | K5: Escala | L5: 1 A 5 DOC
B6: Teléfono | K6: Cantidad | L6: 12
B7: Email
K8: id_receta (auxiliar) | L8: =IFERROR(INDEX(Indice!$A$2:$A$237,MATCH($L$4,Indice!$E$2:$E$237,0)),"") -> 1
B9: ITEM | C9: CANT | D9: DESCRIPCIÓN | E9: COSTO UNIT | F9: TOTAL | H9: Configuración (auxiliar) | I9: Escala (auxiliar) | K9: Descripción | L9: =IFERROR(INDEX(Indice!$B$2:$B$237,MATCH($L$8,Indice!$A$2:$A$237,0))&" — "&INDEX(Indice!$D$2:$D$237,MATCH($L$8,Indice!$A$2:$A$237,0)),"—") -> FRA MUSE MICR — MUSELINA DAMA
K10: Costo interno unitario (USD) | L10: =IFERROR(SUMIFS(M_Recetas!$J$2:$J$2828,M_Recetas!$A$2:$A$2828,$L$8),0) -> 3.6525
K11: Precio unitario (USD) | L11: =IFERROR(INDEX(M_Escalas!$G$2:$G$706,MATCH($L$8&"|"&$L$5,M_Escalas!$I$2:$I$706,0)),"Sin dato — revisar Anomalias") -> 5.844
K12: Margen (USD) | L12: =IF(ISNUMBER($L$11),$L$11-$L$10,"—") -> 2.1915
K13: Margen (%) | L13: =IF(AND(ISNUMBER($L$11),$L$11<>0),$L$12/$L$11,"—") -> 0.375
K15: Desglose del costo interno
K16: Insumo | L16: =IFERROR(SUMIFS(M_Recetas!$J$2:$J$2828,M_Recetas!$A$2:$A$2828,$L$8,M_Recetas!$F$2:$F$2828,"Insumo"),0) -> 2.1025
K17: Proceso | L17: =IFERROR(SUMIFS(M_Recetas!$J$2:$J$2828,M_Recetas!$A$2:$A$2828,$L$8,M_Recetas!$F$2:$F$2828,"Proceso"),0) -> 0.8
K18: Tecnica | L18: =IFERROR(SUMIFS(M_Recetas!$J$2:$J$2828,M_Recetas!$A$2:$A$2828,$L$8,M_Recetas!$F$2:$F$2828,"Tecnica"),0) -> 0
K19: Indirecto | L19: =IFERROR(SUMIFS(M_Recetas!$J$2:$J$2828,M_Recetas!$A$2:$A$2828,$L$8,M_Recetas!$F$2:$F$2828,"Indirecto"),0) -> 0.75
K20: Otro | L20: =IFERROR(SUMIFS(M_Recetas!$J$2:$J$2828,M_Recetas!$A$2:$A$2828,$L$8,M_Recetas!$F$2:$F$2828,"Otro"),0) -> 0
K21: Total (verificación) | L21: =SUM(L16:L20) -> 3.6525
K23: Editar línea Nº (ITEM)
K25: Botones (a asignar tras importar el macro): ① Agregar/Actualizar línea → M01_GestionPresupuesto.AgregarOActualizarItem ② Cargar línea para editar → M01_GestionPresupuesto.CargarItemParaEditar ③ Limpiar configurador → M01_GestionPresupuesto.LimpiarConfigurador ④ Eliminar línea → M01_GestionPresupuesto.EliminarItem
D26: TOTAL A PAGAR | F26: =SUM(F10:F24) -> 0
E27: ABONO:
E28: RESTA: | F28: =F26-F27 -> 0
B30: Términos y condiciones (editable): - Se requiere un abono del 60% del total para dar comienzo al proyecto. - El precio a partir de la talla XL suma un recargo por unidad (definir monto). - La fecha de entrega es estimada. El presupuesto es válido solo para el día especificado.

Sheet M_Recetas
A1: id_receta | B1: hoja | C1: seccion_tecnica | D1: bloque_variante | E1: componente | F1: clasificacion | G1: consumo | H1: precio_unitario | I1: costo_local | J1: costo_usd | K1: origen | L1: formula
A2: 1 | B2: FRA MUSE MICR | C2: MUSELINA DAMA | D2: MUSELINA DAMA | E2: TELA | F2: Insumo | G2: 0.8 | H2: 2.3 | I2: 7360 | J2: 1.84 | K2: FRA MUSE MICR!B4 | L2: fx: 0.8*2.3*E2
A3: 1 | B3: FRA MUSE MICR | C3: MUSELINA DAMA | D3: MUSELINA DAMA | E3: CORTE | F3: Proceso | I3: 700 | J3: 0.175 | K3: FRA MUSE MICR!B5
A4: 1 | B4: FRA MUSE MICR | C4: MUSELINA DAMA | D4: MUSELINA DAMA | E4: COSTURA | F4: Proceso | I4: 2500 | J4: 0.625 | K4: FRA MUSE MICR!B6
A5: 1 | B5: FRA MUSE MICR | C5: MUSELINA DAMA | D5: MUSELINA DAMA | E5: ETIQUETA | F5: Insumo | I5: 200 | J5: 0.05 | K5: FRA MUSE MICR!B7
A6: 1 | B6: FRA MUSE MICR | C6: MUSELINA DAMA | D6: MUSELINA DAMA | E6: BOLSA | F6: Insumo | I6: 100 | J6: 0.025 | K6: FRA MUSE MICR!B8
A7: 1 | B7: FRA MUSE MICR | C7: MUSELINA DAMA | D7: MUSELINA DAMA | E7: MARQUILLA | F7: Insumo | I7: 500 | J7: 0.125 | K7: FRA MUSE MICR!B9
A8: 1 | B8: FRA MUSE MICR | C8: MUSELINA DAMA | D8: MUSELINA DAMA | E8: HILO | F8: Insumo | I8: 250 | J8: 0.0625 | K8: FRA MUSE MICR!B10
A9: 1 | B9: FRA MUSE MICR | C9: MUSELINA DAMA | D9: MUSELINA DAMA | E9: GASTOS OPERATIVOS | F9: Indirecto | I9: 3000 | J9: 0.75 | K9: FRA MUSE MICR!B11
A10: 2 | B10: FRA MUSE MICR | C10: MUSELINA DAMA | D10: MICRO DAMA | E10: TELA | F10: Insumo | G10: 0.8 | H10: 2 | I10: 6400 | J10: 1.6 | K10: FRA MUSE MICR!G4 | L10: fx: 0.8*2*E2
A11: 2 | B11: FRA MUSE MICR | C11: MUSELINA DAMA | D11: MICRO DAMA | E11: CORTE | F11: Proceso | I11: 700 | J11: 0.175 | K11: FRA MUSE MICR!G5
A12: 2 | B12: FRA MUSE MICR | C12: MUSELINA DAMA | D12: MICRO DAMA | E12: COSTURA | F12: Proceso | I12: 2500 | J12: 0.625 | K12: FRA MUSE MICR!G6
A13: 2 | B13: FRA MUSE MICR | C13: MUSELINA DAMA | D13: MICRO DAMA | E13: ETIQUETA | F13: Insumo | I13: 200 | J13: 0.05 | K13: FRA MUSE MICR!G7
A14: 2 | B14: FRA MUSE MICR | C14: MUSELINA DAMA | D14: MICRO DAMA | E14: BOLSA | F14: Insumo | I14: 3000 | J14: 0.75 | K14: FRA MUSE MICR!G8
A15: 2 | B15: FRA MUSE MICR | C15: MUSELINA DAMA | D15: MICRO DAMA | E15: MARQUILLA | F15: Insumo | I15: 500 | J15: 0.125 | K15: FRA MUSE MICR!G9
A16: 2 | B16: FRA MUSE MICR | C16: MUSELINA DAMA | D16: MICRO DAMA | E16: HILO | F16: Insumo | I16: 350 | J16: 0.0875 | K16: FRA MUSE MICR!G10
A17: 2 | B17: FRA MUSE MICR | C17: MUSELINA DAMA | D17: MICRO DAMA | E17: GASTOS OPERATIVOS | F17: Indirecto | I17: 4000 | J17: 1 | K17: FRA MUSE MICR!G11
A18: 3 | B18: FRA MUSE MICR | C18: MUSELINA NIÑO | D18: MUSELINA NIÑO | E18: TELA | F18: Insumo | G18: 0.3 | H18: 1.3 | I18: 1560 | J18: 0.39 | K18: FRA MUSE MICR!B14 | L18: fx: 0.3*1.3*E2
A19: 3 | B19: FRA MUSE MICR | C19: MUSELINA NIÑO | D19: MUSELINA NIÑO | E19: CORTE | F19: Proceso | I19: 500 | J19: 0.125 | K19: FRA MUSE MICR!B15
A20: 3 | B20: FRA MUSE MICR | C20: MUSELINA NIÑO | D20: MUSELINA NIÑO | E20: COSTURA | F20: Proceso | I20: 2000 | J20: 0.5 | K20: FRA MUSE MICR!B16
A21: 3 | B21: FRA MUSE MICR | C21: MUSELINA NIÑO | D21: MUSELINA NIÑO | E21: ETIQUETA | F21: Insumo | I21: 0 | J21: 0 | K21: FRA MUSE MICR!B17
A22: 3 | B22: FRA MUSE MICR | C22: MUSELINA NIÑO | D22: MUSELINA NIÑO | E22: BOLSA | F22: Insumo | I22: 0 | J22: 0 | K22: FRA MUSE MICR!B18
A23: 3 | B23: FRA MUSE MICR | C23: MUSELINA NIÑO | D23: MUSELINA NIÑO | E23: MARQUILLA | F23: Insumo | I23: 0 | J23: 0 | K23: FRA MUSE MICR!B19
A24: 3 | B24: FRA MUSE MICR | C24: MUSELINA NIÑO | D24: MUSELINA NIÑO | E24: HILO | F24: Insumo | I24: 250 | J24: 0.0625 | K24: FRA MUSE MICR!B20
A25: 3 | B25: FRA MUSE MICR | C25: MUSELINA NIÑO | D25: MUSELINA NIÑO | E25: GASTOS OPERATIVOS | F25: Indirecto | I25: 2000 | J25: 0.5 | K25: FRA MUSE MICR!B21
A26: 4 | B26: FRA MUSE MICR | C26: MUSELINA NIÑO | D26: MICRO NIÑO | E26: TELA | F26: Insumo | G26: 0.6 | H26: 2 | I26: 4800 | J26: 1.2 | K26: FRA MUSE MICR!G14 | L26: fx: 0.6*2*E2
A27: 4 | B27: FRA MUSE MICR | C27: MUSELINA NIÑO | D27: MICRO NIÑO | E27: CORTE | F27: Proceso | I27: 700 | J27: 0.175 | K27: FRA MUSE MICR!G15
A28: 4 | B28: FRA MUSE MICR | C28: MUSELINA NIÑO | D28: MICRO NIÑO | E28: COSTURA | F28: Proceso | I28: 3000 | J28: 0.75 | K28: FRA MUSE MICR!G16
A29: 4 | B29: FRA MUSE MICR | C29: MUSELINA NIÑO | D29: MICRO NIÑO | E29: ETIQUETA | F29: Insumo | G29: 0.6 | H29: 12000 | I29: 7200 | J29: 1.8 | K29: FRA MUSE MICR!G17 | L29: fx: 0.6*12000
A30: 4 | B30: FRA MUSE MICR | C30: MUSELINA NIÑO | D30: MICRO NIÑO | E30: BOLSA | F30: Insumo | I30: 0 | J30: 0 | K30: FRA MUSE MICR!G18
A31: 4 | B31: FRA MUSE MICR | C31: MUSELINA NIÑO | D31: MICRO NIÑO | E31: MARQUILLA | F31: Insumo | I31: 0 | J31: 0 | K31: FRA MUSE MICR!G19
A32: 4 | B32: FRA MUSE MICR | C32: MUSELINA NIÑO | D32: MICRO NIÑO | E32: HILO | F32: Insumo | I32: 250 | J32: 0.0625 | K32: FRA MUSE MICR!G20
A33: 4 | B33: FRA MUSE MICR | C33: MUSELINA NIÑO | D33: MICRO NIÑO | E33: GASTOS OPERATIVOS | F33: Indirecto | I33: 0 | J33: 0 | K33: FRA MUSE MICR!G21
A34: 5 | B34: FRA MUSE MICR | C34: MUSELINA CABALLERO | D34: MUSELINA CABALLERO | E34: TELA | F34: Insumo | G34: 0.9 | H34: 1.5 | I34: 5400 | J34: 1.35 | K34: FRA MUSE MICR!B24 | L34: fx: 0.9*1.5*E2
A35: 5 | B35: FRA MUSE MICR | C35: MUSELINA CABALLERO | D35: MUSELINA CABALLERO | E35: CORTE | F35: Proceso | I35: 300 | J35: 0.075 | K35: FRA MUSE MICR!B25
A36: 5 | B36: FRA MUSE MICR | C36: MUSELINA CABALLERO | D36: MUSELINA CABALLERO | E36: COSTURA | F36: Proceso | I36: 1800 | J36: 0.45 | K36: FRA MUSE MICR!B26
A37: 5 | B37: FRA MUSE MICR | C37: MUSELINA CABALLERO | D37: MUSELINA CABALLERO | E37: BORDADO | F37: Proceso | I37: 2500 | J37: 0.625 | K37: FRA MUSE MICR!B27
A38: 5 | B38: FRA MUSE MICR | C38: MUSELINA CABALLERO | D38: MUSELINA CABALLERO | E38: ETIQUETA | F38: Insumo | I38: 50 | J38: 0.0125 | K38: FRA MUSE MICR!B28
A39: 5 | B39: FRA MUSE MICR | C39: MUSELINA CABALLERO | D39: MUSELINA CABALLERO | E39: BOLSA | F39: Insumo | I39: 50 | J39: 0.0125 | K39: FRA MUSE MICR!B29
A40: 5 | B40: FRA MUSE MICR | C40: MUSELINA CABALLERO | D40: MUSELINA CABALLERO | E40: HILO | F40: Insumo | I40: 250 | J40: 0.0625 | K40: FRA MUSE MICR!B30 | L40: fx: B20
...

Sheet M_Escalas
A1: id_receta | B1: hoja | C1: bloque | D1: escala | E1: factor | F1: costo_usd | G1: precio_usd | H1: celda | I1: clave
A2: 1 | B2: FRA MUSE MICR | C2: MUSELINA DAMA | D2: +5 DOC | E2: 1.4 | F2: 3.6525 | G2: 5.1135 | H2: C8 | I2: =A2&"|"&TRIM(D2) -> 1|+5 DOC
A3: 1 | B3: FRA MUSE MICR | C3: MUSELINA DAMA | D3: 1 A 5 DOC | E3: 1.6 | F3: 3.6525 | G3: 5.844 | H3: D8 | I3: =A3&"|"&TRIM(D3) -> 1|1 A 5 DOC
A4: 1 | B4: FRA MUSE MICR | C4: MUSELINA DAMA | D4: DETAL | E4: 1.99 | F4: 3.6525 | G4: 7.268475 | H4: E8 | I4: =A4&"|"&TRIM(D4) -> 1|DETAL
A5: 2 | B5: FRA MUSE MICR | C5: MICRO DAMA | D5: +5 DOC | E5: 1.3 | F5: 4.4125 | G5: 5.73625 | H5: H8 | I5: =A5&"|"&TRIM(D5) -> 2|+5 DOC
A6: 2 | B6: FRA MUSE MICR | C6: MICRO DAMA | D6: 1 A 5 DOC | E6: 1.5 | F6: 4.4125 | G6: 6.61875 | H6: I8 | I6: =A6&"|"&TRIM(D6) -> 2|1 A 5 DOC
A7: 2 | B7: FRA MUSE MICR | C7: MICRO DAMA | D7: DETAL | E7: 1.7 | F7: 4.4125 | G7: 7.50125 | H7: J8 | I7: =A7&"|"&TRIM(D7) -> 2|DETAL
A8: 3 | B8: FRA MUSE MICR | C8: MUSELINA NIÑO | D8: +5 DOC | E8: 1.3 | F8: 1.5775 | G8: 2.05075 | H8: C17 | I8: =A8&"|"&TRIM(D8) -> 3|+5 DOC
A9: 3 | B9: FRA MUSE MICR | C9: MUSELINA NIÑO | D9: 1 A 5 DOC | E9: 1.5 | F9: 1.5775 | G9: 2.36625 | H9: D17 | I9: =A9&"|"&TRIM(D9) -> 3|1 A 5 DOC
A10: 3 | B10: FRA MUSE MICR | C10: MUSELINA NIÑO | D10: DETAL | E10: 1.99 | F10: 1.5775 | G10: 3.139225 | H10: E17 | I10: =A10&"|"&TRIM(D10) -> 3|DETAL
A11: 4 | B11: FRA MUSE MICR | C11: MICRO NIÑO | D11: +5 DOC | E11: 1.4 | F11: 3.9875 | G11: 5.5825 | H11: H17 | I11: =A11&"|"&TRIM(D11) -> 4|+5 DOC
A12: 4 | B12: FRA MUSE MICR | C12: MICRO NIÑO | D12: 1 A 5 DOC | E12: 1.6 | F12: 3.9875 | G12: 6.38 | H12: I17 | I12: =A12&"|"&TRIM(D12) -> 4|1 A 5 DOC
A13: 4 | B13: FRA MUSE MICR | C13: MICRO NIÑO | D13: DETAL | E13: 1.99 | F13: 3.9875 | G13: 7.935125 | H13: J17 | I13: =A13&"|"&TRIM(D13) -> 4|DETAL
... A706: 236 | B706: TOP DAMA | C706: CABALLERO | D706: DETAL | E706: 1.99 | F706: 3.4888889 | G706: 6.9428889 | H706: M39 | I706: =A706&"|"&TRIM(D706) -> 236|DETAL

Sheet M_Insumos
A1: insumo | B1: costo_local | C1: tasa | D1: costo_usd | E1: origen
A2: TELA | B2: 7360 | C2: 4000 | D2: 1.84 | E2: FRA MUSE MICR!B4
A3: TELA | B3: 6400 | C3: 4000 | D3: 1.6 | E3: FRA MUSE MICR!G4
A4: TELA | B4: 1560 | C4: 4000 | D4: 0.39 | E4: FRA MUSE MICR!B14
A5: TELA | B5: 4800 | C5: 4000 | D5: 1.2 | E5: FRA MUSE MICR!G14
A6: TELA | B6: 5400 | C6: 4000 | D6: 1.35 | E6: FRA MUSE MICR!B24
A7: TELA | B7: 9200 | C7: 4000 | D7: 2.3 | E7: FRA MUSE MICR!G24
A8: TELA | B8: 5760 | C8: 4000 | D8: 1.44 | E8: FRA MUSE MICR!G37
A9: TELA | B9: 7360 | C9: 4000 | D9: 1.84 | E9: FRA MUSE MICR!B52
A10: TELA | B10: 4800 | C10: 4000 | D10: 1.2 | E10: FRA MUSE MICR!G52
A11: TELA | B11: 3960 | C11: 4000 | D11: 0.99 | E11: FRA MUSE MICR!B68
A12: TELA | B12: 6400 | C12: 4000 | D12: 1.6 | E12: FRA MUSE MICR!G68
A13: TELA | B13: 4480 | C13: 4000 | D13: 1.12 | E13: FRA MUSE MICR!B86
... A1140: TELA TULL | B1140: 12150 | C1140: 4500 | D1140: 2.7 | E1140: TUTU !B8

Sheet M_Procesos
A1: proceso | B1: tarifa_local | C1: tasa | D1: tarifa_usd | E1: origen
A2: CORTE | B2: 700 | C2: 4000 | D2: 0.175 | E2: FRA MUSE MICR!B5
A3: CORTE | B3: 700 | C3: 4000 | D3: 0.175 | E3: FRA MUSE MICR!G5
A4: CORTE | B4: 500 | C4: 4000 | D4: 0.125 | E4: FRA MUSE MICR!B15
A5: CORTE | B5: 700 | C5: 4000 | D5: 0.175 | E5: FRA MUSE MICR!G15
A6: CORTE | B6: 300 | C6: 4000 | D6: 0.075 | E6: FRA MUSE MICR!B25
A7: CORTE | B7: 700 | C7: 4000 | D7: 0.175 | E7: FRA MUSE MICR!G25
A8: CORTE | B8: 700 | C8: 4000 | D8: 0.175 | E8: FRA MUSE MICR!B38
A9: CORTE | B9: 700 | C9: 4000 | D9: 0.175 | E9: FRA MUSE MICR!G38
A10: CORTE | B10: 700 | C10: 4000 | D10: 0.175 | E10: FRA MUSE MICR!B53
A11: CORTE | B11: 700 | C11: 4000 | D11: 0.175 | E11: FRA MUSE MICR!G53
A12: CORTE | B12: 700 | C12: 4000 | D12: 0.175 | E12: FRA MUSE MICR!B69
A13: CORTE | B13: 700 | C13: 4000 | D13: 0.175 | E13: FRA MUSE MICR!G69
... A1176: DIGITALIZACION | B1176: 3000 | C1176: 4000 | D1176: 0.75 | E1176: CAMISAS !R11

Sheet Anomalias
A1: tipo | B1: hoja | C1: celda | D1: detalle | E1: bloque | F1: gravedad
A2: a) Tasa incrustada distinta | B2: FRA MUSE MICR | C2: G111 | D2: 3800 vs tasa 4000 | E2: MICRO CABALLERO | F2: ALTA
A3: a) Tasa incrustada distinta | B3: FRA MUSE MICR | C3: G253 | D3: 8500 vs tasa 4000 | E3: CABALLERO | F3: ALTA
A4: a) Tasa incrustada distinta | B4: BUZO | C4: J45 | D4: 9500 vs tasa 4000 | E4: BUZO CABALLERO | F4: ALTA
A5: a) Tasa incrustada distinta | B5: CV TASLAN | C5: Y28 | D5: 3700 vs tasa 3900 | E5: CORTA VIENTO CABALLERO | F5: ALTA
A6: a) Tasa incrustada distinta | B6: CV MEMORY | C6: B24 | D6: 3500 vs tasa 4000 | E6: CORTA VIENTO NIÑO | F6: ALTA
A7: a) Tasa incrustada distinta | B7: CV MEMORY | C7: B25 | D7: 6000 vs tasa 4000 | E7: CORTA VIENTO NIÑO | F7: ALTA
A8: a) Tasa incrustada distinta | B8: KSAKAS | C8: B23 | D8: 8500 vs tasa 4000 | E8: KASAKAS SUBLIMACION TOTAL | F8: ALTA
A9: a) Tasa incrustada distinta | B9: UNI FUTBOL | C9: B7 | D9: 8500 vs tasa 4000 | E9: MUSELINA | F9: ALTA
A10: a) Tasa incrustada distinta | B10: UNI FUTBOL | C10: B50 | D10: 9500 vs tasa 4000 | E10: MUSELINA | F10: ALTA
A11: a) Tasa incrustada distinta | B11: UNI FUTBOL | C11: J87 | D11: 4000 vs tasa 3800 | E11: NIÑO | F11: ALTA
A12: a) Tasa incrustada distinta | B12: UNI FUTBOL | C12: J125 | D12: 3800 vs tasa 4000 | E12: CABALLERO | F12: ALTA
... A24: a) Tasa incrustada distinta | B24: FRANELILLAS | C24: B83 | D24: 3800 vs tasa 4000 | E24: MUSE | F24: ALTA
A25: g) Insumo con precios distintos | B25: FRA MUSE MICR | C25: TELA | D25: 104 valores: [840, 950, 1170, 1560, 1800, 2025] | F25: MEDIA
A26: g) Insumo con precios distintos | B26: FRA MUSE MICR | C26: ETIQUETA | D26: 12 valores: [50, 65, 80, 100, 132, 200] | F26: MEDIA
A27: g) Insumo con precios distintos | B27: FRA MUSE MICR | C27: BOLSA | D27: 8 valores: [50, 60, 100, 150, 500, 530] | F27: MEDIA
A28: g) Insumo con precios distintos | B28: FRA MUSE MICR | C28: MARQUILLA | D28: 14 valores: [50, 60, 70, 100, 200, 250] | F28: MEDIA
A29: g) Insumo con precios distintos | B29: FRA MUSE MICR | C29: HILO | D29: 7 valores: [100, 200, 250, 300, 350, 500] | F29: MEDIA
A30: g) Insumo con precios distintos | B30: CHALECOS | C30: CIERRE | D30: 9 valores: [1200, 1300, 1500, 1800, 2000, 2500] | F30: MEDIA
A31: g) Insumo con precios distintos | B31: HODDI MONO | C31: TELA MONO | D31: 11 valores: [7200.0, 7600, 13200.0, 13875, 15000, 16530] | F31: MEDIA
A32: g) Insumo con precios distintos | B32: SUETER | C32: TELA DE MONO | D32: 3 valores: [13680, 16720, 18240] | F32: MEDIA
A33: g) Insumo con precios distintos | B33: SHORT | C33: CAUCHO | D33: 10 valores: [200, 500, 600, 800, 1000, 1100] | F33: MEDIA
A34: g) Insumo con precios distintos | B34: CV TASLAN | C34: TELA TASLAN | D34: 7 valores: [12540.0, 17550, 18000, 20520, 20900, 28500] | F34: MEDIA
A35: g) Insumo con precios distintos | B35: CV MEMORY | C35: TELA MEMORY | D35: 5 valores: [8640, 11400, 12920, 13680, 15200] | F35: MEDIA
A36: g) Insumo con precios distintos | B36: KSAKAS | C36: TELA MALLA | D36: 2 valores: [2400, 2880] | F36: MEDIA
... A62: g) Proceso con precios distintos | B62: BOLSAS POP | C62: DTF | D62: 2 valores: [800, 1500] | F62: MEDIA

Sheet Indice
A1: id_receta | B1: hoja | C1: seccion_tecnica | D1: bloque_variante | E1: Etiqueta
A2: 1 | B2: FRA MUSE MICR | C2: MUSELINA DAMA | D2: MUSELINA DAMA | E2: =TRIM(B2)&" — "&TRIM(D2)&" [#"&A2&"]" -> FRA MUSE MICR — MUSELINA DAMA [#1]
A3: 2 | B3: FRA MUSE MICR | C3: MUSELINA DAMA | D3: MICRO DAMA | E3: =TRIM(B3)&" — "&TRIM(D3)&" [#"&A3&"]" -> FRA MUSE MICR — MICRO DAMA [#2]
A4: 3 | B4: FRA MUSE MICR | C4: MUSELINA NIÑO | D4: MUSELINA NIÑO | E4: =TRIM(B4)&" — "&TRIM(D4)&" [#"&A4&"]" -> FRA MUSE MICR — MUSELINA NIÑO [#3]
A5: 4 | B5: FRA MUSE MICR | C5: MUSELINA NIÑO | D5: MICRO NIÑO | E5: =TRIM(B5)&" — "&TRIM(D5)&" [#"&A5&"]" -> FRA MUSE MICR — MICRO NIÑO [#4]
A6: 5 | B6: FRA MUSE MICR | C6: MUSELINA CABALLERO | D6: MUSELINA CABALLERO | E6: =TRIM(B6)&" — "&TRIM(D6)&" [#"&A6&"]" -> FRA MUSE MICR — MUSELINA CABALLERO [#5]
A7: 6 | B7: FRA MUSE MICR | C7: MUSELINA CABALLERO | D7: MICRO CABALLERO | E7: =TRIM(B7)&" — "&TRIM(D7)&" [#"&A7&"]" -> FRA MUSE MICR — MICRO CABALLERO [#6]
A8: 7 | B8: FRA MUSE MICR | C8: MUSELINA DAMA | D8: MUSELINA DAMA | E8: =TRIM(B8)&" — "&TRIM(D8)&" [#"&A8&"]" -> FRA MUSE MICR — MUSELINA DAMA [#7]
A9: 8 | B9: FRA MUSE MICR | C9: MUSELINA DAMA | D9: MUSELINA NIÑO | E9: =TRIM(B9)&" — "&TRIM(D9)&" [#"&A9&"]" -> FRA MUSE MICR — MUSELINA NIÑO [#8]
A10: 9 | B10: FRA MUSE MICR | C10: MICRO DAMA | D10: MICRO DAMA | E10: =TRIM(B10)&" — "&TRIM(D10)&" [#"&A10&"]" -> FRA MUSE MICR — MICRO DAMA [#9]
A11: 10 | B11: FRA MUSE MICR | C11: MICRO DAMA | D11: MICRO NIÑO | E11: =TRIM(B11)&" — "&TRIM(D11)&" [#"&A11&"]" -> FRA MUSE MICR — MICRO NIÑO [#10]
A12: 11 | B12: FRA MUSE MICR | C12: MUSE CABALLERO | D12: MUSE CABALLERO | E12: =TRIM(B12)&" — "&TRIM(D12)&" [#"&A12&"]" -> FRA MUSE MICR — MUSE CABALLERO [#11]
A13: 12 | B13: FRA MUSE MICR | C13: MUSE CABALLERO | D13: MICRO CABALLERO | E13: =TRIM(B13)&" — "&TRIM(D13)&" [#"&A13&"]" -> FRA MUSE MICR — MICRO CABALLERO [#12]
... A75: 74 | B75: SUETER | C75: SUETER CABALLERO | D75: SUETER CABALLERO | E75: =TRIM(B75)&" — "&TRIM(D75)&" [#"&A75&"]" -> SUETER — SUETER CABALLERO [#74]
A76: 75 | B76: BUZO | D76: BUZO DAMA | E76: =TRIM(B76)&" — "&TRIM(D76)&" [#"&A76&"]" -> BUZO — BUZO DAMA [#75]
A77: 76 | B77: BUZO | D77: BUZO DAMA | E77: =TRIM(B77)&" — "&TRIM(D77)&" [#"&A77&"]" -> BUZO — BUZO DAMA [#76]
A78: 77 | B78: BUZO | D78: BUZO DAMA | E78: =TRIM(B78)&" — "&TRIM(D78)&" [#"&A78&"]" -> BUZO — BUZO DAMA [#77]
A79: 78 | B79: BUZO | D79: BUZO DAMA | E79: =TRIM(B79)&" — "&TRIM(D79)&" [#"&A79&"]" -> BUZO — BUZO DAMA [#78]
A80: 79 | B80: BUZO | D80: BUZO DAMA | E80: =TRIM(B80)&" — "&TRIM(D80)&" [#"&A80&"]" -> BUZO — BUZO DAMA [#79]
A81: 80 | B81: BUZO | D81: BUZO DAMA | E81: =TRIM(B81)&" — "&TRIM(D81)&" [#"&A81&"]" -> BUZO — BUZO DAMA [#80]
A82: 81 | B82: BUZO | D82: BUZO DAMA | E82: =TRIM(B82)&" — "&TRIM(D82)&" [#"&A82&"]" -> BUZO — BUZO DAMA [#81]
A83: 82 | B83: BUZO | D83: BUZO NIÑO | E83: =TRIM(B83)&" — "&TRIM(D83)&" [#"&A83&"]" -> BUZO — BUZO NIÑO [#82]
A84: 83 | B84: BUZO | D84: BUZO NIÑO | E84: =TRIM(B84)&" — "&TRIM(D84)&" [#"&A84&"]" -> BUZO — BUZO NIÑO [#83]
A85: 84 | B85: BUZO | D85: BUZO NIÑO | E85: =TRIM(B85)&" — "&TRIM(D85)&" [#"&A85&"]" -> BUZO — BUZO NIÑO [#84]
A86: 85 | B86: BUZO | D86: BUZO NIÑO | E86: =TRIM(B86)&" — "&TRIM(D86)&" [#"&A86&"]" -> BUZO — BUZO NIÑO [#85]
A87: 86 | B87: BUZO | D87: BUZO NIÑO | E87: =TRIM(B87)&" — "&TRIM(D87)&" [#"&A87&"]" -> BUZO — BUZO NIÑO [#86]
... A98: 97 | B98: SHORT | D98: SHORT NIÑO | E98: =TRIM(B98)&" — "&TRIM(D98)&" [#"&A98&"]" -> SHORT — SHORT NIÑO [#97]
A99: 98 | B99: SHORT | C99: GASTOS OPERATIVOS | D99: SHORT DAMA | E99: =TRIM(B99)&" — "&TRIM(D99)&" [#"&A99&"]" -> SHORT — SHORT DAMA [#98]
A100: 99 | B100: SHORT | C100: SHORT CABALLERO | D100: SHORT CABALLERO | E100: =TRIM(B100)&" — "&TRIM(D100)&" [#"&A100&"]" -> SHORT — SHORT CABALLERO [#99]
A101: 100 | B101: SHORT | C101: GASTOS OPERATIVOS | D101: SHORT NIÑO | E101: =TRIM(B101)&" — "&TRIM(D101)&" [#"&A101&"]" -> SHORT — SHORT NIÑO [#100]
A102: 101 | B102: SHORT | C102: GASTOS OPERATIVOS | D102: SHORT DAMA | E102: =TRIM(B102)&" — "&TRIM(D102)&" [#"&A102&"]" -> SHORT — SHORT DAMA [#101]
A103: 102 | B103: SHORT | C103: SHORT CABALLERO | D103: SHORT CABALLERO | E103: =TRIM(B103)&" — "&TRIM(D103)&" [#"&A103&"]" -> SHORT — SHORT CABALLERO [#102]
A104: 103 | B104: SHORT | C104: GASTOS OPERATIVOS | D104: SHORT NIÑO | E104: =TRIM(B104)&" — "&TRIM(D104)&" [#"&A104&"]" -> SHORT — SHORT NIÑO [#103]
A105: 104 | B105: SHORT | C105: GASTOS OPERATIVOS | D105: SHORT DAMA | E105: =TRIM(B105)&" — "&TRIM(D105)&" [#"&A105&"]" -> SHORT — SHORT DAMA [#104]
A106: 105 | B106: SHORT | C106: SHORT CABALLERO | D106: SHORT CABALLERO | E106: =TRIM(B106)&" — "&TRIM(D106)&" [#"&A106&"]" -> SHORT — SHORT CABALLERO [#105]
A107: 106 | B107: CV TASLAN | C107: CORTA VIENTO DAMA | D107: CORTA VIENTO DAMA | E107: =TRIM(B107)&" — "&TRIM(D107)&" [#"&A107&"]" -> CV TASLAN — CORTA VIENTO DAMA [#106]
A108: 107 | B108: CV TASLAN | C108: CORTA VIENTO DAMA | D108: CORTA VIENTO DAMA | E108: =TRIM(B108)&" — "&TRIM(D108)&" [#"&A108&"]" -> CV TASLAN — CORTA VIENTO DAMA [#107]
A109: 108 | B109: CV TASLAN | C109: CORTA VIENTO CABALLERO | D109: CORTA VIENTO CABALLERO | E109: =TRIM(B109)&" — "&TRIM(D109)&" [#"&A109&"]" -> CV TASLAN — CORTA VIENTO CABALLERO [#108]
A110: 109 | B110: CV TASLAN | C110: CORTA VIENTO CABALLERO | D110: CORTA VIENTO CABALLERO | E110: =TRIM(B110)&" — "&TRIM(D110)&" [#"&A110&"]" -> CV TASLAN — CORTA VIENTO CABALLERO [#109]
... A112: 111 | B112: CV TASLAN | C112: CORTA VIENTO CABALLERO | D112: PANTALON DE MONO | E112: =TRIM(B112)&" — "&TRIM(D112)&" [#"&A112&"]" -> CV TASLAN — PANTALON DE MONO [#111]
...
