Workbook

Sheet P COSTURA
A2: NJ STORE | F2: NJ SPORT
A3: DESCRIPCION | B3: UNIDAD | C3: DOCENA | D3: MAYOR | F3: DESCRIPCION | G3: UNIDAD | H3: DOCENA | I3: MAYOR
A4: CORTE | B4: 700 | C4: 500 | D4: 300 | F4: CORTE | G4: 700 | H4: 500 | I4: 300
A5: PLANCHADA | B5: 500 | C5: 400 | D5: 250 | F5: PLANCHADA | G5: 500 | H5: 400 | I5: 250
A7: COSTURA | B7: UNIDAD | C7: DOCENA | D7: MAYOR | F7: COSTURA | G7: UNIDAD | H7: DOCENA | I7: MAYOR
A8: FRANELA | B8: 3000 | C8: 2000 | D8: 1600 | F8: FRANELA | G8: 2500 | H8: 2000 | I8: 1600
A9: CHEMIS | B9: 5000 | C9: 4000 | D9: 2500 | F9: CHEMIS | G9: 3500 | H9: 3000 | I9: 2500 | L9: =2000*2000/4000 -> 1000
A10: CHEMIS CON UNIONES DE TELAS | B10: 8000 | C10: 7000 | D10: 6000
A11: SUETER CON GORRO | B11: 4500 | C11: 3000 | D11: 2500 | F11: SUETER CON GORRO | G11: 3500 | H11: 3000 | I11: 2500
A12: SUETER SIMPLE | B12: 4000 | C12: 3000 | D12: 2000 | F12: SUETER SIMPLE | G12: 3000 | H12: 2500 | I12: 2000
A13: SHORT | B13: 2500 | C13: 1800 | D13: 1200 | F13: SHORT | G13: 2000 | H13: 1800 | I13: 1200
A14: SHORT CON BOLSILLO | B14: 3000 | C14: 2500 | F14: MONO | G14: 4000 | H14: 3000 | I14: 2500
A15: MONO | B15: 5000 | C15: 4000 | D15: 2500 | F15: PORTA CANILLERAS C/ CORTE | G15: 1500 | H15: 1200 | I15: 900
A16: PORTA CANILLERAS C/ CORTE | B16: 2500 | C16: 1200 | D16: 900 | F16: FUNDA PORTA CANILLERA S/C | G16: 1500 | H16: 1200 | I16: 900
A17: FUNDA PORTA CANILLERA S/C | B17: 1500 | C17: 1200 | D17: 900 | F17: LICRA | G17: 3500 | H17: 3200 | I17: 2800
A18: LICRA | B18: 4000 | C18: 3200 | D18: 2800 | F18: VELAS | G18: 2500 | H18: 2200 | I18: 2000
A19: VELAS SENCILLA | B19: 3000 | C19: 2200 | D19: 2000 | F19: PROTECTORES ARQUEROS | G19: 1000 | H19: 900 | I19: 700
A20: PROTECTORES ARQUEROS | B20: 1000 | C20: 900 | D20: 700 | F20: WALL MEDIA | G20: 4500 | H20: 4300 | I20: 4000
A21: WALL MEDIA | B21: 4500 | C21: 4000 | D21: 4000 | F21: BOLSA DE ARENA | G21: 1500 | H21: 1300 | I21: 1100
A22: BOLSA DE ARENA | B22: 1500 | C22: 1300 | D22: 1100 | F22: TOP DAMA | G22: 3000 | H22: 2500 | I22: 2000
A23: TOP DAMA | B23: 3000 | C23: 2500 | D23: 2000 | F23: CHALECOS CON BOLSILLOS | G23: 4000 | H23: 3500 | I23: 3000
A24: CHALECOS CON BOLSILLOS | B24: 4000 | C24: 3500 | D24: 3000 | F24: COJINES | G24: 2000 | H24: 1800 | I24: 1500
A25: COJINES | B25: 2000 | C25: 1800 | D25: 1500 | F25: CHAQUETAS SENCILLAS | G25: 4000 | H25: 3500 | I25: 3000
A26: CHAQUETAS SENCILLAS | B26: 4000 | C26: 3500 | D26: 3000 | F26: CHAQUETAS FORRADAS | G26: 6000 | H26: 5500 | I26: 5000
... A28: QUIRURGICOS CORTE | B28: 1400 | C28: 1200 | D28: 1000 | F28: QUIRURGICOS COSTURA | G28: 6000 | H28: 5000 | I28: 4500
A29: QUIRURGICOS COSTURA | B29: 6000 | C29: 5000 | D29: 4500
A30: FALDA SHORT CON BOLSILLO | B30: 5000 | C30: 4000 | D30: 3500
A31: FALDA SHORT | B31: 4000 | C31: 3500 | D31: 3000
A32: BUZOS | B32: 3500 | C32: 2500
A33: CAMISAS

Sheet COJINES
A1: COJINES
F2: 3800
A3: TELA | B3: =7/12*F2 -> 2216.6667
A4: CORTE | B4: 500
A5: COSTURA | B5: 2000 | D5: tulas con delantero sublimado
A6: SUBLIMACION | B6: =13000/12 -> 1083.3333
A7: PLANCHA | B7: 500 | D7: +5 DOC | E7: 1 A 5 DOC | F7: DETAL
A8: DISEÑO | B8: 1000 | D8: =D13 -> 4.4333333 | E8: =E13 -> 5.5416667 | F8: =F13 -> 6.3016667
A9: TELA PELUCHE | B9: =5/12*F2 -> 1583.3333
A10: CINTA DE MARCA | B10: 300
A11: ETIQUETA | B11: 500
B12: 0 | D12: 0.4 | E12: 0.6 | F12: 0.9
A13: HILO | B13: =350 -> 350 | D13: =B15*1.4/F2 -> 4.4333333 | E13: =B15*1.75/F2 -> 5.5416667 | F13: =B15*1.99/F2 -> 6.3016667
A14: GASTOS OPERATIVOS | B14: =2000 -> 2000
B15: =SUM(B3:B14) -> 12033.333

Sheet FRA MUSE MICR
A1: FRANELAS EN BLANCO
E2: 4000
A3: MUSELINA DAMA | F3: MICRO DAMA
A4: TELA | B4: =0.8*2.3*E2 -> 7360 | F4: TELA | G4: =0.8*2*E2 -> 6400
A5: CORTE | B5: 700 | F5: CORTE | G5: 700
A6: COSTURA | B6: 2500 | C6: +5 DOC | D6: 1 A 5 DOC | E6: DETAL | F6: COSTURA | G6: 2500 | H6: +5 DOC | I6: 1 A 5 DOC | J6: DETAL
A7: ETIQUETA | B7: 200 | C7: 30 | D7: 50 | E7: 99 | F7: ETIQUETA | G7: 200 | H7: 40 | I7: 60 | J7: 99
A8: BOLSA | B8: 100 | C8: =B12*1.4 -> 5.1135 | D8: =B12*1.6 -> 5.844 | E8: =B12*1.99 -> 7.268475 | F8: BOLSA | G8: 3000 | H8: =G12*1.3 -> 5.73625 | I8: =G12*1.5 -> 6.61875 | J8: =G12*1.7 -> 7.50125
A9: MARQUILLA | B9: 500 | F9: MARQUILLA | G9: 500 | H9: =H8*3800 -> 21797.75 | I9: =I8*3800 -> 25151.25 | J9: =J8*3800 -> 28504.75
A10: HILO | B10: 250 | F10: HILO | G10: 350
A11: GASTOS OPERATIVOS | B11: 3000 | F11: GASTOS OPERATIVOS | G11: 4000
B12: =SUM(B4:B11)/E2 -> 3.6525 | G12: =SUM(G4:G11)/E2 -> 4.4125
A13: MUSELINA NIÑO | F13: MICRO NIÑO
A14: TELA | B14: =0.3*1.3*E2 -> 1560 | F14: TELA | G14: =0.6*2*E2 -> 4800
A15: CORTE | B15: 500 | C15: +5 DOC | D15: 1 A 5 DOC | E15: DETAL | F15: CORTE | G15: 700 | H15: +5 DOC | I15: 1 A 5 DOC | J15: DETAL
A16: COSTURA | B16: 2000 | C16: 30 | D16: 50 | E16: 99 | F16: COSTURA | G16: 3000 | H16: 30 | I16: 50 | J16: 99
A17: ETIQUETA | B17: 0 | C17: =B22*1.3 -> 2.05075 | D17: =B22*1.5 -> 2.36625 | E17: =B22*1.99 -> 3.139225 | F17: ETIQUETA | G17: =0.6*12000 -> 7200 | H17: =G22*1.4 -> 5.5825 | I17: =G22*1.6 -> 6.38 | J17: =G22*1.99 -> 7.935125
A18: BOLSA | B18: 0 | F18: BOLSA | G18: 0
A19: MARQUILLA | B19: 0 | F19: MARQUILLA | G19: 0
A20: HILO | B20: 250 | F20: HILO | G20: 250
A21: GASTOS OPERATIVOS | B21: 2000 | F21: GASTOS OPERATIVOS | G21: 0
B22: =SUM(B14:B21)/E2 -> 1.5775 | G22: =SUM(G14:G21)/E2 -> 3.9875
A23: MUSELINA CABALLERO | F23: MICRO CABALLERO
A24: TELA | B24: =0.9*1.5*E2 -> 5400 | F24: TELA | G24: =1*2.3*E2 -> 9200 | H24: =400*3700/G24 -> 160.86957
A25: CORTE | B25: 300 | C25: +5 DOC | D25: 1 A 5 DOC | E25: DETAL | F25: CORTE | G25: 700 | H25: +5 DOC | I25: 1 A 5 DOC | J25: DETAL
A26: COSTURA | B26: 1800 | C26: 30 | D26: 50 | E26: 99 | F26: COSTURA | G26: 3500 | H26: 40 | I26: 60 | J26: 99
A27: BORDADO | B27: 2500 | C27: =B32*1.4 -> 3.9725 | D27: =B32*1.6 -> 4.54 | E27: =B32*1.99 -> 5.646625 | F27: MARQUILLA | G27: 200 | H27: =G32*1.3 -> 8.10875 | I27: =G32*1.7 -> 10.60375 | J27: =G32*1.9 -> 11.85125
A28: ETIQUETA | B28: 50 | E28: *0 | F28: ETIQUETA | G28: 100 | H28: =H27*3800 -> 30813.25 | I28: =I27*3800 -> 40294.25 | J28: =J27*3800 -> 45034.75
A29: BOLSA | B29: 50 | F29: BOLSA | G29: =11000 -> 11000
A30: HILO | B30: =B20 -> 250 | F30: HILO | G30: =B30 -> 250
A31: GASTOS OPERATIVOS | B31: 1000 | F31: GASTOS OPERATIVOS | G31: 0
B32: =SUM(B24:B31)/E2 -> 2.8375 | G32: =SUM(G24:G31)/E2 -> 6.2375
A35: REPLICA DE MARCAS VINIL MEDIANO/PÑO
A36: MUSELINA DAMA | F36: MUSELINA NIÑO
A37: TELA | B37: 0 | F37: TELA | G37: =0.8*1.8*4000 -> 5760
A38: CORTE | B38: 700 | F38: CORTE | G38: 700
A39: COSTURA | B39: 2500 | F39: COSTURA | G39: 3500
A40: PLANCHA | B40: 1000 | F40: PLANCHA | G40: 1000
A41: VINIL 15 CMS | B41: 5000 | F41: VINIL 15 CMS | G41: 700
A42: CORTE DEL PLOTTER | B42: 200 | C42: +5 DOC | D42: 1 A 5 DOC | E42: DETAL | F42: CORTE DEL PLOTTER | G42: 0 | H42: +5 DOC | I42: 1 A 5 DOC | J42: DETAL
...

Sheet VESTIDO PROMOTORA
A2: LICRA UNICOLOR
A3: DAMA
A4: TELA | B4: =1.8*6*4000 -> 43200
A5: CORTE | B5: 2500
A6: COSTURA | B6: 12000
A7: PLANCHA | B7: 1250
A8: VINIL 15 CMS | B8: 2500 | D8: +5 DOC | E8: 1 A 5 DOC | F8: DETAL
A9: DISEÑO | B9: 1000 | D9: =D14 -> 24.269375 | E9: =E14 -> 26.78 | F9: =F14 -> 33.307625
A10: CORTE DEL PLOTTER | B10: 200
A11: DEPILADA | B11: 200
A12: ETIQUETA | B12: 0
A13: BOLSA | B13: 0 | D13: 0.4 | E13: 0.55 | F13: 0.85
A14: HILO | B14: 350 | D14: =B17*1.45 -> 24.269375 | E14: =B17*1.6 -> 26.78 | F14: =B17*1.99 -> 33.307625
A15: MARQUILLA | B15: 250
A16: GASTOS OPERATIVOS | B16: 3500
B17: =SUM(B4:B16)/4000 -> 16.7375
A19: LICRA SUBLIMADO
A20: DAMA
A21: TELA | B21: =1.8*6*4000 -> 43200
A22: CORTE | B22: 2500
A23: COSTURA | B23: 12000
A24: PLANCHA | B24: 1250
A25: SUBLIMACION | B25: =0.5*11000 -> 5500 | D25: +5 DOC | E25: 1 A 5 DOC | F25: DETAL
A26: DISEÑO | B26: 1000 | D26: =D31 -> 25.356875 | E26: =E31 -> 27.98 | F26: =F31 -> 34.800125
A27: CORTE DEL PLOTTER | B27: 200
A28: DEPILADA | B28: 200
A29: ETIQUETA | B29: 0
A30: BOLSA | B30: 0 | D30: 0.4 | E30: 0.55 | F30: 0.85
A31: HILO | B31: 350 | D31: =B34*1.45 -> 25.356875 | E31: =B34*1.6 -> 27.98 | F31: =B34*1.99 -> 34.800125
A32: MARQUILLA | B32: 250
A33: GASTOS OPERATIVOS | B33: 3500
B34: =SUM(B21:B33)/4000 -> 17.4875

Sheet WALL MEDIA 
A3: WALL 1*2 | J3: WALL 0,5*2
A4: 2 curvas pvc 3/4 (2700$) | B4: =2*2700 -> 5400 | F4: 4000 | G4: DÓLAR | J4: 2 curvas pvc 3/4 (2700$) | K4: =2*2700 -> 5400
A5: tubo pvc 3/4 5 mts (4,82m) 11$ | B5: =4.9*11/6*F4 -> 35933.333 | J5: tubo pvc 3/4 5 mts (4,47m) 11$ | K5: =4.5*11/6*3800 -> 31350
A6: tubo pvc caliente 1/2 x 50cm (5$) | B6: =0.5*5/3*F4 -> 3333.3333 | J6: tubo pvc caliente 1/2 x 50cm (5$) | K6: =0.5*5/3*3800 -> 3166.6667
A7: tubo aluminio 1/2*6cm (5$) | B7: =0.06*5/6*F4 -> 200 | E7: WALL 1*2 | J7: tubo aluminio 1/2*6cm (5$) | K7: =0.06*5/6*3800 -> 190
A8: tubo pvc 1/2 x 1,40cm (9$) | B8: =1.4*5/6*F4 -> 4666.6667 | D8: 50CMSX2MTS | J8: tubo pvc 1/2 x 0,9cm (9$) | K8: =0.9*5/6*3800 -> 2850
A9: goma pvc x 1 wall media | B9: =6*1/30*F4 -> 800 | J9: goma pvc x 1 wall media | K9: =6*1/30*3800 -> 760
A10: tees pvc 1/2 x 2 | B10: =2*2500 -> 5000 | D10: 35 | E10: 65 | F10: 99 | H10: COSTO | J10: tees pvc 1/2 x 2 | K10: =2*2500 -> 5000
A11: tubo base MT 24cm x2 | B11: =0.24*10/3*F4 -> 3200 | D11: =H11*1.35 -> 56.065263 | E11: =H11*1.65 -> 68.524211 | F11: =H11*1.8 -> 74.753684 | H11: =B27 -> 41.529825 | J11: tubo base MT 24cm x2 | K11: =0.24*10/3*3800 -> 3040
A12: tubo base x2 | B12: =2*3000 -> 6000 | J12: tubo base x2 | K12: =2*3000 -> 6000
A13: tornillos 9mm drywall x 8 | B13: =8*100 -> 800 | J13: tornillos 9mm drywall x 8 | K13: =8*100 -> 800
A14: pintura aerosol x 6 piezas GRIS | B14: =14000/3 -> 4666.6667 | J14: pintura aerosol x 6 piezas GRIS | K14: =14000/3 -> 4666.6667
A15: pintura aerosol x 2 piezas NEGRA | B15: =14000/6 -> 2333.3333 | J15: pintura aerosol x 2 piezas NEGRA | K15: =14000/6 -> 2333.3333
A16: MDF 9mm x 2 | B16: =1600*2 -> 3200 | E16: WALL 0,5*2 | J16: MDF 9mm x 2 | K16: =1600*2 -> 3200
A17: corte MDF x 2 | B17: 6000 | D17: 90CMS * 2MTS | J17: corte MDF x 2 | K17: 6000
A18: goma zapatera x 4 | B18: 500 | D18: 35 | E18: 65 | F18: 99 | H18: COSTO | J18: goma zapatera x 4 | K18: 500
A19: microporosa x 4 | B19: =250*4 -> 1000 | D19: =H19*1.35 -> 40.714816 | E19: =H19*1.65 -> 49.762553 | F19: =H19*1.8 -> 54.286421 | H19: =K27 -> 30.159123 | J19: microporosa x 4 | K19: =250*4 -> 1000
A20: tornillos aluminio x 2 | B20: 650*2 | J20: tornillos aluminio x 2 | K20: 650*2
A21: tela atletica trasera negra 53*220 | B21: =1.8*2.2*F4 -> 15840 | J21: tela atletica trasera negra 53*220 | K21: =1.8*2.2*3800/2 -> 7524
A22: tela atletica blanca 53*220 | B22: =2.2*1.8*F4 -> 15840 | J22: tela atletica blanca 53*220 | K22: =2.2*1.8*3800/2 -> 7524
A23: impresión y calandra 53*220 (18000$) | B23: =2.2*18000 -> 39600 | E23: PURA FUNDA IMPRESA 2*1 | J23: impresión y calandra 53*220 (18000$) | K23: =2.2*18000/2 -> 19800
A24: costura | B24: 2500 | F24: 35$ | J24: costura | K24: 2500
A25: cierre magico x1mts | B25: 1000 | J25: cierre magico x1mts | K25: 1000
A26: total | B26: =SUM(B4:B25) -> 157813.33 | C26: PESOS | J26: total | K26: =SUM(K4:K25) -> 114604.67 | L26: PESOS
B27: =B26/3800 -> 41.529825 | C27: DÓLAR | K27: =K26/3800 -> 30.159123 | L27: DÓLAR

Sheet WALL 
A1: WALL 1*2
A2: tela garbadina 4 mts | B2: =4*4.5 -> 18
A3: tela para patas | B3: =0.3*2 -> 0.6
A4: sublimacion 4 | B4: 0
A5: costura | B5: =8000/4000 -> 2
A6: corte | B6: =1000/4000 -> 0.25 | D6: DETAL | E6: MAYOR 12
D7: =B11*1.68 -> 35.028 | E7: =B11*1.35 -> 28.1475
A11: total | B11: =SUM(B2:B10) -> 20.85

Sheet LANYARD
A2: LANYARD
A3: CINTA | B3: 1000
A4: MOSQUETON | B4: 800
A5: CLIKCLAK | B5: 300
A6: SUBLIMACION | B6: =0.9*11000/11 -> 900
A7: PLANCHA | B7: 250
A8: CORTE | B8: 500
A9: HILO | B9: 250 | D9: 40% | E9: 65% | F9: 90%
A10: COSTURA | B10: 1500 | D10: =B12*1.4 -> 2.1875 | E10: =B12*1.65 -> 2.578125 | F10: =B12*1.99 -> 3.109375
A11: GASTOS OPERATIVOS | B11: 1750
B12: =SUM(B4:B11)/4000 -> 1.5625

Sheet franelas cucuta
D1: FRANELAS EN BLANCO
E2: 3800 | P2: FRANELAS EN BLANCO
A3: COTTONE DAMA | H3: COTTONE CABALLERO
A4: TELA | B4: =0.8*4.2*E2 -> 12768 | H4: TELA | I4: =1*4.2*E2 -> 15960 | O4: COTTONE DAMA | S4: COTTONE CABALLERO
A5: CORTE | B5: 500 | H5: CORTE | I5: 500 | O5: +5 DOC | P5: 1 A 5 DOC | Q5: DETAL | S5: +5 DOC | T5: 1 A 5 DOC | U5: DETAL
A6: COSTURA | B6: 2500 | H6: COSTURA | I6: 2500 | O6: 40 | P6: 60 | Q6: 99 | S6: 40 | T6: 60 | U6: 99
A7: ETIQUETA | B7: 250 | D7: +5 DOC | E7: 1 A 5 DOC | F7: DETAL | H7: ETIQUETA | I7: 250 | K7: +5 DOC | L7: 1 A 5 DOC | M7: DETAL | O7: =D9 -> 7.6882105 | P7: =E9 -> 8.7865263 | Q7: =F9 -> 10.928242 | S7: =K9 -> 8.8642105 | T7: =L9 -> 10.130526 | U7: =M9 -> 12.599842
A8: BOLSA | B8: 100 | D8: 40 | E8: 60 | F8: 99 | H8: BOLSA | I8: 100 | K8: 40 | L8: 60 | M8: 99
A9: MARQUILLA | B9: 500 | D9: =B12*1.4 -> 7.6882105 | E9: =B12*1.6 -> 8.7865263 | F9: =B12*1.99 -> 10.928242 | H9: MARQUILLA | I9: 500 | K9: =I12*1.4 -> 8.8642105 | L9: =I12*1.6 -> 10.130526 | M9: =I12*1.99 -> 12.599842 | O9: KEIRA PLUS DAMA | S9: KEIRA PLUS CABALLERO
A10: HILO | B10: 250 | H10: HILO | I10: =B10 -> 250 | O10: +5 DOC | P10: 1 A 5 DOC | Q10: DETAL | S10: +5 DOC | T10: 1 A 5 DOC | U10: DETAL
A11: GASTOS OPERATIVOS | B11: 4000 | H11: GASTOS OPERATIVOS | I11: =B11 -> 4000 | O11: 40 | P11: 60 | Q11: 99 | S11: 40 | T11: 60 | U11: 99
B12: =SUM(B4:B11)/E2 -> 5.4915789 | I12: =SUM(I4:I11)/E2 -> 6.3315789 | O12: =D20 -> 6.1202105 | P12: =E20 -> 6.9945263 | Q12: =F20 -> 8.6994421 | S12: =K20 -> 6.9042105 | T12: =L20 -> 7.8905263 | U12: =M20 -> 9.8138421
A14: KEIRA PLUS DAMA | H14: KEIRA PLUS CABALLERO | O14: CENTAURO DAMA | S14: CENTAURO CABALLERO
A15: TELA | B15: =0.8*2.8*E2 -> 8512 | H15: TELA | I15: =1*2.8*E2 -> 10640 | O15: +5 DOC | P15: 1 A 5 DOC | Q15: DETAL | S15: +5 DOC | T15: 1 A 5 DOC | U15: DETAL
A16: CORTE | B16: =B5 -> 500 | H16: CORTE | I16: 500 | O16: 40 | P16: 60 | Q16: 99 | S16: 40 | T16: 60 | U16: 99
A17: COSTURA | B17: =B6 -> 2500 | H17: COSTURA | I17: 2500 | O17: =D31 -> 7.2402105 | P17: =E31 -> 8.2745263 | Q17: =F31 -> 10.291442 | S17: =K30 -> 8.8282895 | T17: =L30 -> 10.463158 | U17: =M30 -> 13.013553
A18: ETIQUETA | B18: 250 | D18: +5 DOC | E18: 1 A 5 DOC | F18: DETAL | H18: ETIQUETA | I18: 250 | K18: +5 DOC | L18: 1 A 5 DOC | M18: DETAL
A19: BOLSA | B19: 100 | D19: 40 | E19: 60 | F19: 99 | H19: BOLSA | I19: 100 | K19: 40 | L19: 60 | M19: 99 | O19: CENTAHELADA DA FRIA | S19: CENTAHELADA CAB
A20: MARQUILLA | B20: 500 | D20: =B23*1.4 -> 6.1202105 | E20: =B23*1.6 -> 6.9945263 | F20: =B23*1.99 -> 8.6994421 | H20: MARQUILLA | I20: 500 | K20: =I23*1.4 -> 6.9042105 | L20: =I23*1.6 -> 7.8905263 | M20: =I23*1.99 -> 9.8138421 | O20: +5 DOC | P20: 1 A 5 DOC | Q20: DETAL | S20: +5 DOC | T20: 1 A 5 DOC | U20: DETAL
A21: HILO | B21: 250 | H21: HILO | I21: 250 | O21: 40 | P21: 60 | Q21: 99 | S21: 40 | T21: 60 | U21: 99
A22: GASTOS OPERATIVOS | B22: 4000 | H22: GASTOS OPERATIVOS | I22: 4000 | O22: =D41 -> 7.9122105 | P22: =E41 -> 9.0425263 | Q22: =F41 -> 11.246642 | S22: =K41 -> 9.1442105 | T22: =L41 -> 10.450526 | U22: =M41 -> 12.997842
B23: =SUM(B15:B22)/E2 -> 4.3715789 | I23: =SUM(I15:I22)/E2 -> 4.9315789
H24: CENTAURO CABALLERO | O24: CENTAURO EGIPCIO DA FRIA | S24: CENTAURO EGIPCIO CAB
A25: CENTAURO DAMA | H25: TELA | I25: =1*4*E2 -> 15200 | O25: +5 DOC | P25: 1 A 5 DOC | Q25: DETAL | S25: +5 DOC | T25: 1 A 5 DOC | U25: DETAL
A26: TELA | B26: =0.8*3.8*E2 -> 11552 | H26: CORTE | I26: 500 | O26: 40 | P26: 60 | Q26: 99 | S26: 40 | T26: 60 | U26: 99
A27: CORTE | B27: =B16 -> 500 | H27: COSTURA | I27: 2000 | O27: =D51 -> 7.3522105 | P27: =E51 -> 8.4025263 | Q27: =F51 -> 10.450642 | S27: =K51 -> 8.4442105 | T27: =L51 -> 9.6505263 | U27: =M51 -> 12.002842
A28: COSTURA | B28: =B17 -> 2500 | H28: MARQUILLA | I28: 500 | K28: +5 DOC | L28: 1 A 5 DOC | M28: DETAL
A29: MARQUILLA | B29: 500 | D29: +5 DOC | E29: 1 A 5 DOC | F29: DETAL | H29: ETIQUETA | I29: 250 | K29: 40 | L29: 60 | M29: 99 | O29: MICRO DAMA | S29: MICRO CABALLERO
A30: ETIQUETA | B30: 250 | D30: 40 | E30: 60 | F30: 99 | H30: BOLSA | I30: 100 | K30: =I34*1.35 -> 8.8282895 | L30: =I34*1.6 -> 10.463158 | M30: =I34*1.99 -> 13.013553 | O30: +5 DOC | P30: 1 A 5 DOC | Q30: DETAL | S30: +5 DOC | T30: 1 A 5 DOC | U30: DETAL
A31: BOLSA | B31: 100 | D31: =B34*1.4 -> 7.2402105 | E31: =B34*1.6 -> 8.2745263 | F31: =B34*1.99 -> 10.291442 | H31: HILO | I31: 300 | O31: 40 | P31: 60 | Q31: 99 | S31: 40 | T31: 60 | U31: 99
A32: HILO | B32: 250 | H32: VINIL | I32: 4000 | O32: ='FRA MUSE MICR'!H8 -> 5.73625 | P32: ='FRA MUSE MICR'!I8 -> 6.61875 | Q32: ='FRA MUSE MICR'!J8 -> 7.50125 | S32: ='FRA MUSE MICR'!H27 -> 8.10875 | T32: ='FRA MUSE MICR'!I27 -> 10.60375 | U32: ='FRA MUSE MICR'!J27 -> 11.85125
A33: GASTOS OPERATIVOS | B33: 4000 | H33: GASTOS OPERATIVOS | I33: 2000
B34: =SUM(B26:B33)/E2 -> 5.1715789 | I34: =SUM(I25:I33)/E2 -> 6.5394737 | O34: MUSELINA DAMA | S34: MUSELINA CABALLERO
A35: CENTAHELADA DAMA | H35: CENTAHELADA CAB | O35: +5 DOC | P35: 1 A 5 DOC | Q35: DETAL | S35: +5 DOC | T35: 1 A 5 DOC | U35: DETAL
A36: TELA | B36: =0.8*4.4*E2 -> 13376 | H36: TELA | I36: =1*4.4*E2 -> 16720 | O36: 40 | P36: 60 | Q36: 99 | S36: 40 | T36: 60 | U36: 99
A37: CORTE | B37: 500 | H37: CORTE | I37: 500 | O37: ='FRA MUSE MICR'!C8 -> 5.1135 | P37: ='FRA MUSE MICR'!D8 -> 5.844 | Q37: ='FRA MUSE MICR'!E8 -> 7.268475 | S37: ='FRA MUSE MICR'!C27 -> 3.9725 | T37: ='FRA MUSE MICR'!D27 -> 4.54 | U37: ='FRA MUSE MICR'!E27 -> 5.646625
A38: COSTURA | B38: 2500 | H38: COSTURA | I38: 2500
A39: MARQUILLA | B39: 500 | D39: +5 DOC | E39: 2 A 5 DOC | F39: DETAL | H39: MARQUILLA | I39: 500 | K39: +5 DOC | L39: 2 A 5 DOC | M39: DETAL
A40: ETIQUETA | B40: 250 | D40: 40 | E40: 60 | F40: 99 | H40: ETIQUETA | I40: 250 | K40: 40 | L40: 60 | M40: 99
A41: BOLSA | B41: 100 | D41: =B44*1.4 -> 7.9122105 | E41: =B44*1.6 -> 9.0425263 | F41: =B44*1.99 -> 11.246642 | H41: BOLSA | I41: 100 | K41: =I44*1.4 -> 9.1442105 | L41: =I44*1.6 -> 10.450526 | M41: =I44*1.99 -> 12.997842
...

Sheet CHALECOS
E2: DRILL SAHARA
A3: CORTA VIENTO DAMA | D3: CON VINIL PÑO
A4: TELA DRILL SAHARA | B4: =1*2.3*F4 -> 8740 | F4: 3800 | G4: DÓLAR
A5: CORTE | B5: 500
A6: COSTURA | B6: 6000
A7: CIERRE | B7: 2500
A8: PLANCHA | B8: 0 | D8: CORTA VIENTO DE DAMA IMPERMEABLE
A9: VINIL 15 CMS | B9: =1*11000 -> 11000
A10: DISEÑO | B10: 2000 | D10: +5 DOC | E10: 1 A 5 DOC | F10: DETAL
A11: CORTE DEL PLOTTER | B11: 0 | D11: =D15 -> 14.463947 | E11: =E15 -> 16.330263 | F11: =F15 -> 18.569842
A12: DEPILADA | B12: 0
A13: ETIQUETA | B13: 200
A14: BOLSA | B14: 100 | D14: 45 | E14: 75 | F14: 99
A15: HILO | B15: 350 | D15: =B18*1.55 -> 14.463947 | E15: =B18*1.75 -> 16.330263 | F15: =B18*1.99 -> 18.569842
A16: MARQUILLA | B16: 70
A17: GASTOS OPERATIVOS | B17: 4000
B18: =SUM(B4:B17)/F4 -> 9.3315789
E20: MEMORY
A21: CHALECO TODO SUBLIMADO
A22: TELA | B22: =1*4*F22 -> 15200 | F22: 3800 | G22: DÓLAR
A23: CORTE | B23: 700
A24: COSTURA | B24: 6000
A25: CIERRE | B25: 2500
A26: PLANCHA | B26: 1500 | D26: CORTA VIENTO DE DAMA IMPERMEABLE
A27: VINIL | B27: 2500
A28: DISEÑO | B28: 2000 | D28: +5 DOC | E28: 1 A 5 DOC | F28: DETAL
A29: CORTE DEL PLOTTER | B29: 200 | D29: =D33 -> 14.325263 | E29: =E33 -> 14.787368 | F29: =F33 -> 17.56
A30: DEPILADA | B30: 200
A31: ETIQUETA | B31: 200
A32: BOLSA | B32: 100 | D32: 45 | E32: 75 | F32: 99
A33: HILO | B33: 250 | D33: =B36*1.55 -> 14.325263 | E33: =B36*1.6 -> 14.787368 | F33: =B36*1.9 -> 17.56
A34: MARQUILLA | B34: 70
A35: GASTOS OPERATIVOS | B35: 3700
B36: =SUM(B22:B35)/F22 -> 9.2421053

Sheet FRA ALGODON
A1: ALGODÓN EN BLANCO
A2: DAMA | F2: 3800 | G2: DÓLAR
A3: TELA | B3: =0.8*5.31*F2 -> 16142.4
A4: CORTE | B4: 1000
A5: COSTURA | B5: 2500 | D5: +5 DOC | E5: 1 A 5 DOC | F5: DETAL
A6: PLANCHA | B6: 0 | D6: =D12 -> 9.9372316 | E6: =E12 -> 11.993211 | F6: =F12 -> 13.637994
A7: DISEÑO | B7: 1000
A8: CORTE DEL PLOTTER | B8: 0
A9: DEPILADA | B9: 0
A10: ETIQUETA | B10: 200
A11: BOLSA | B11: 100 | D11: 0.4 | E11: 0.6 | F11: 0.9
A12: HILO | B12: 350 | D12: =B15*1.45 -> 9.9372316 | E12: =B15*1.75 -> 11.993211 | F12: =B15*1.99 -> 13.637994
A13: MARQUILLA | B13: 750
A14: GASTOS OPERATIVOS | B14: 4000
B15: =SUM(B3:B14)/F2 -> 6.8532632
A19: CABALLERO | D19: ALGODÓN EN BLANCO
A20: TELA | B20: =1.1*1.9*F2 -> 7942
A21: CORTE | B21: 700
A22: COSTURA | B22: 2500
A23: PLANCHA | B23: 1000
A24: VINIL | B24: 4500 | D24: +5 DOC | E24: 1 A 5 DOC | F24: DETAL
A25: DISEÑO | B25: 1000 | D25: =D30 -> 8.0291842 | E25: =E30 -> 8.3060526 | F25: =F30 -> 11.019363
A26: CORTE DEL PLOTTER | B26: 0
A27: DEPILADA | B27: 0
A28: ETIQUETA | B28: 0
A29: BOLSA | B29: 100 | D29: 0.4 | E29: 0.55 | F29: 0.85
A30: HILO | B30: 350 | D30: =B33*1.45 -> 8.0291842 | E30: =B33*1.5 -> 8.3060526 | F30: =B33*1.99 -> 11.019363
A31: MARQUILLA | B31: 250
A32: GASTOS OPERATIVOS | B32: 2700
B33: =SUM(B20:B32)/F2 -> 5.5373684
A37: ALGODÓN CON DISEÑO VINIL
A38: DAMA
A39: TELA | B39: =0.8*5.31*F2 -> 16142.4
A40: CORTE | B40: 1000
A41: COSTURA | B41: 2500
A42: PLANCHA | B42: 1000
A43: VINIL 15 CMS | B43: 1000 | D43: +5 DOC | E43: 1 A 5 DOC | F43: DETAL
A44: DISEÑO | B44: 1000 | D44: =D49 -> 10.853021 | E44: =E49 -> 13.098474 | F44: =F49 -> 14.894836
A45: CORTE DEL PLOTTER | B45: 200
A46: DEPILADA | B46: 200
...

Sheet HODDI  MONO
A1: HODDI CON GORRO EN BLANCO TELA DE MONO
A2: DAMA | F2: 3800 | G2: DÓLAR
A3: TELA MONO | B3: =1.7*4*F2 -> 25840
A4: CORTE | B4: 1000 | H4: HODDI CON DISEÑO EN VINIL
A5: COSTURA | B5: 4500 | H5: DAMA
A6: PLANCHA | B6: 0 | D6: DAMA | H6: TELA MONO | I6: =1.8*2.9*F2 -> 19836
A7: DISEÑO | B7: 0 | D7: +5 DOC | E7: 1 A 5 DOC | F7: DETAL | H7: CORTE | I7: 700
A8: CORTE DEL PLOTTER | B8: 0 | D8: =D12 -> 14.000132 | E8: =E12 -> 16.896711 | F8: =F12 -> 19.213974 | H8: COSTURA | I8: 3000
A9: DEPILADA | B9: 0 | H9: PLANCHA | I9: 3000 | K9: DAMA
A10: ETIQUETA | B10: 200 | H10: sublimacion | I10: =1.8*13000 -> 23400 | K10: +5 DOC | L10: 1 A 5 DOC | M10: DETAL
A11: BOLSA | B11: 100 | D11: 0.4 | E11: 0.6 | F11: 0.9 | H11: CORDON | I11: 1000
A12: HILO | B12: 300 | D12: =B15*1.45 -> 14.000132 | E12: =B15*1.75 -> 16.896711 | F12: =B15*1.99 -> 19.213974 | H12: DISEÑO | I12: 2000 | K12: =K17 -> 20.706868 | L12: =L17 -> 26.842237 | M12: =M17 -> 30.523458
A13: MARQUILLA | B13: 750 | H13: ETIQUETA | I13: 200
A14: GASTOS OPERATIVOS | B14: 4000 | H14: BOLSA | I14: 100
B15: =SUM(B3:B14)/F2 -> 9.6552632 | H15: HILO | I15: 300
H16: MARQUILLA | I16: 750 | K16: 0.4 | L16: 0.6 | M16: 0.9
H17: GASTOS OPERATIVOS | I17: 4000 | K17: =I18*1.35 -> 20.706868 | L17: =I18*1.75 -> 26.842237 | M17: =I18*1.99 -> 30.523458
A18: NIÑO | I18: =SUM(I6:I17)/F2 -> 15.338421
A19: TELA MONO | B19: =1.5*4*F2 -> 22800
A20: CORTE | B20: 1000
A21: COSTURA | B21: 4000 | D21: NIÑO
A22: PLANCHA | B22: 0 | D22: +5 DOC | E22: 1 A 5 DOC | F22: DETAL
A23: DISEÑO | B23: =B7 -> 0 | D23: =D27 -> 12.649342 | E23: =E27 -> 15.266447 | F23: =F27 -> 17.360132 | H23: NIÑO
A24: CORTE DEL PLOTTER | B24: =B8 -> 0 | H24: TELA MONO | I24: =1.5*2.9*F2 -> 16530
A25: DEPILADA | B25: =B9 -> 0 | H25: CORTE | I25: 700 | K25: NIÑO
A26: ETIQUETA | B26: 200 | D26: 0.4 | E26: 0.6 | F26: 0.9 | H26: COSTURA | I26: 3000 | K26: +5 DOC | L26: 1 A 5 DOC | M26: DETAL
A27: BOLSA | B27: 100 | D27: =B31*1.45 -> 12.649342 | E27: =B31*1.75 -> 15.266447 | F27: =B31*1.99 -> 17.360132 | H27: PLANCHA | I27: 1000 | K27: =K33 -> 17.436316 | L27: =L33 -> 21.956842 | M27: =M33 -> 25.702421
A28: HILO | B28: =B12 -> 300 | H28: sublimacion | I28: =1.5*13000 -> 19500
A29: MARQUILLA | B29: =B13 -> 750 | H29: CORDON | I29: 1000
A30: GASTOS OPERATIVOS | B30: =B14 -> 4000 | H30: DISEÑO | I30: =I12 -> 2000
B31: =SUM(B19:B30)/F2 -> 8.7236842 | H31: ETIQUETA | I31: 200
H32: BOLSA | I32: 100 | K32: 0.4 | L32: 0.6 | M32: 0.9
A33: CABALLERO | H33: HILO | I33: =I15 -> 300 | K33: =I36*1.35 -> 17.436316 | L33: =I36*1.7 -> 21.956842 | M33: =I36*1.99 -> 25.702421
A34: TELA MONO | B34: =2*4*F2 -> 30400 | H34: MARQUILLA | I34: =I16 -> 750
A35: CORTE | B35: 700 | H35: GASTOS OPERATIVOS | I35: =I17 -> 4000
A36: COSTURA | B36: 3500 | I36: =SUM(I24:I35)/F2 -> 12.915789
A37: PLANCHA | B37: 0
A38: VINIL | B38: 2000
A39: DISEÑO | B39: 1000 | D39: CABALLERO
A40: CORTE DEL PLOTTER | B40: 200 | D40: +5 DOC | E40: 1 A 5 DOC | F40: DETAL | H40: CABALLERO
...

Sheet TAPASOL
A3: FECHA: 20 MAYO DE 2025
A6: Presupuesto
A9: ARTICULO | B9: CATEGORIA | C9: TECNICA | D9: DISEÑO | E9: CANT | F9: PRECIO ($)
A11: TAPASOL | B11: ARTICULOS | C11: SUBLIMACIÓN | D11: REMAX | E11: 1 | F11: 25
A13: TAPASOL | B13: ARTICULOS | C13: SUBLIMACIÓN | D13: REMAX | E13: 12 | F13: 20
A15: TAPASOL | B15: ARTICULOS | C15: SUBLIMACIÓN | D15: REMAX | E15: 36 | F15: 18
A19: NOTAS: - SE REQUIERE UN ABONO DEL 60% DEL TOTAL, PARA DAR COMIENZO AL PROYECTO. - EL DISEÑO VA INCLUÍDO EN EL PROYECTO. - LA FECHA DE ENTREGA ES ESTIMADA. - EL PRESUPUESTO ES VÁLIDO PARA EL DÍA ESPECIFICADO, PUEDE VARIAR POSTERIORMENTE.

Sheet CHAQUETA NORF
A3: CHAQUETA NORT | F3: 3800
A4: CAB
A5: TELA norface 5,5$ | B5: =2*5.5*3800 -> 41800
A6: CORTE | B6: 700
A7: COSTURA | B7: 10000
A8: CIERRE BOLSILLOS | B8: 2800 | D8: DAMA
A9: CIERRE | B9: 3000 | D9: +5 DOC | E9: 1 A 5 DOC | F9: DETAL
A10: CORDON | B10: 0
A11: DISEÑO | B11: 1000 | D11: =D16 -> 24.440132 | E11: =E16 -> 29.496711 | F11: =F16 -> 32.025
A12: CORTE DEL PLOTTER | B12: 0
A13: DEPILADA | B13: 0
A14: ETIQUETA | B14: 0
A15: BOLSA | B15: 0 | D15: 0.4 | E15: 0.6 | F15: 0.9
A16: HILO | B16: 300 | D16: =B19*1.45 -> 24.440132 | E16: =B19*1.75 -> 29.496711 | F16: =B19*1.9 -> 32.025
A17: MARQUILLA | B17: 750
A18: GASTOS OPERATIVOS | B18: 3700
B19: =SUM(B5:B18)/F3 -> 16.855263

Sheet PANTALON MONO
A2: PANTALON DE MONO
A3: DAMA | F3: 4000
A4: TELA MONO | B4: =1.1*3*F3 -> 13200
A5: CORTE | B5: 7000
A6: COSTURA | B6: 3500
A7: PLANCHA | B7: 1000 | D7: PANTALON MONO DAMA
A8: CORTE DEL PLOTTER | B8: 200 | D8: +5 DOC | E8: 1 A 5 DOC | F8: DETAL
A9: VINIL | B9: 1500 | D9: =D13 -> 11.581875 | E9: =E13 -> 13.978125 | F9: =F13 -> 15.895125
A10: DEPILADA | B10: 200
A11: ETIQUETA | B11: 200
A12: BOLSA | B12: 100 | D12: 0.4 | E12: 0.6 | F12: 0.9
A13: HILO | B13: 300 | D13: =B16*1.45 -> 11.581875 | E13: =B16*1.75 -> 13.978125 | F13: =B16*1.99 -> 15.895125
A14: MARQUILLA | B14: 750
A15: GASTOS OPERATIVOS | B15: 4000
B16: =SUM(B4:B15)/F3 -> 7.9875
A19: HODDI NIÑO
A20: TELA MONO | B20: =0.6*3*F3 -> 7200
A21: CORTE | B21: 700
A22: COSTURA | B22: 2500 | D22: PANTALON MONO NIÑO
A23: PLANCHA | B23: 1000 | D23: +5 DOC | E23: 1 A 5 DOC | F23: DETAL
A24: VINIL | B24: 1000 | D24: =D28 -> 6.10875 | E24: =E28 -> 7.91875 | F24: =F28 -> 9.00475
A25: CORTE DEL PLOTTER | B25: =B8 -> 200
A26: DEPILADA | B26: 500
A27: ETIQUETA | B27: 200 | D27: 0.4 | E27: 0.6 | F27: 0.9
A28: MARQUILLA | B28: 500 | D28: =B32*1.35 -> 6.10875 | E28: =B32*1.75 -> 7.91875 | F28: =B32*1.99 -> 9.00475
A29: HILO | B29: =B13 -> 300
A30: DISEÑO | B30: 2000
A31: GASTOS OPERATIVOS | B31: 2000
B32: =SUM(B20:B31)/F3 -> 4.525
A34: HODDI EN BLANCO
A35: HODDI CABALLERO
A36: TELA MONO | B36: =1.25*3*F3 -> 15000
A37: CORTE | B37: 1000
A38: COSTURA | B38: 4000
A39: PLANCHA | B39: 1000
A40: VINIL | B40: 2500 | D40: PANTALON MONO CABALLERO
A41: CORTE DEL PLOTTER | B41: 200 | D41: +5 DOC | E41: 1 A 5 DOC | F41: DETAL
A42: DEPILADA | B42: 200 | D42: =D46 -> 10.603125 | E42: =E46 -> 12.796875 | F42: =F46 -> 14.551875
A43: ETIQUETA | B43: 200
A44: BOLSA | B44: 100
...

Sheet HODDI TERRY
A1: HODDI DAMA | C1: EN BLANCO
A2: TELA TERRY SPUN | B2: =1.8*5.2*F2 -> 37440 | F2: 4000 | G2: DÓLAR
A3: CORTE | B3: 1000
A4: COSTURA | B4: 4500
A5: PLANCHA | B5: 0
A6: DISEÑO | B6: 0 | D6: HODDI TERRY EN BLANCO DAMA
A7: CORTE DEL PLOTTER | B7: 0 | D7: +5 DOC | E7: 1 A 5 DOC | F7: DETAL
A8: DEPILADA | B8: 0 | D8: =D13 -> 17.505125 | E8: =E13 -> 21.126875 | F8: =F13 -> 24.024275
A9: ETIQUETA | B9: 200
A10: BOLSA | B10: 100
A11: HILO | B11: 300 | D11: 0.4 | E11: 0.6 | F11: 0.9
A12: MARQUILLA | B12: 750 | D12: =B14*1.45 -> 70020.5 | E12: =B14*1.75 -> 84507.5 | F12: =B14*1.99 -> 96097.1
A13: GASTOS OPERATIVOS | B13: 4000 | D13: =D12/F2 -> 17.505125 | E13: =E12/F2 -> 21.126875 | F13: =F12/F2 -> 24.024275
B14: =SUM(B2:B13) -> 48290
A18: NIÑO
A19: TELA TERRY SPUN | B19: =1.5*5.2*F2 -> 31200
A20: CORTE | B20: 1000
A21: COSTURA | B21: 4500 | D21: HODDI TERRY EN BLANCO NIÑO
A22: PLANCHA | B22: 0 | D22: +5 DOC | E22: 1 A 5 DOC | F22: DETAL
A23: DISEÑO | B23: =B6 -> 0 | D23: =D30 -> 15.243125 | E23: =E30 -> 18.396875 | F23: =F30 -> 20.919875
A24: CORTE DEL PLOTTER | B24: =B7 -> 0
A25: DEPILADA | B25: =B8 -> 0
A26: ETIQUETA | B26: 200
A27: BOLSA | B27: 100
A28: HILO | B28: =B11 -> 300 | D28: 0.4 | E28: 0.6 | F28: 0.9
A29: MARQUILLA | B29: =B12 -> 750 | D29: =B31*1.45 -> 60972.5 | E29: =B31*1.75 -> 73587.5 | F29: =B31*1.99 -> 83679.5
A30: GASTOS OPERATIVOS | B30: =B13 -> 4000 | D30: =D29/F2 -> 15.243125 | E30: =E29/F2 -> 18.396875 | F30: =F29/F2 -> 20.919875
B31: =SUM(B19:B30) -> 42050
A38: HODDI CABALLERO | C38: EN BLANCO
A39: TELA TERRY SPUN | B39: =2*5.2*F2 -> 41600
A40: CORTE | B40: 1000
A41: COSTURA | B41: 4500
A42: PLANCHA | B42: 0 | D42: HODDI TERRY EN BLANCO CABALLERO
A43: DISEÑO | B43: 1000 | D43: +5 DOC | E43: 1 A 5 DOC | F43: DETAL
A44: CORTE DEL PLOTTER | B44: 0 | D44: =D48 -> 19.375625 | E44: =E48 -> 23.384375 | F44: =F48 -> 26.591375
A45: DEPILADA | B45: 0
A46: ETIQUETA | B46: 200 | D46: 0.4 | E46: 0.6 | F46: 0.9
A47: BOLSA | B47: 100 | D47: =B51*1.45 -> 77502.5 | E47: =B51*1.75 -> 93537.5 | F47: =B51*1.99 -> 106365.5
A48: HILO | B48: 300 | D48: =D47/F2 -> 19.375625 | E48: =E47/F2 -> 23.384375 | F48: =F47/F2 -> 26.591375
A49: MARQUILLA | B49: 750
...

Sheet SUETER
A1: SUETER SIN GORRO | C1: DAMA EN BLANCO | H1: SUETER SIN GORRO | J1: NIÑO EN BLANCO
A2: TELA DE MONO | B2: =1.1*4*F2 -> 16720 | F2: 3800 | H2: TELA DE MONO | I2: =0.9*4*M2 -> 13680 | M2: 3800
A3: CORTE | B3: 700 | H3: CORTE | I3: 700
A4: COSTURA | B4: 4000 | D4: DAMA | H4: COSTURA | I4: 4000 | K4: DAMA
A5: PLANCHA | B5: 1000 | D5: +5 DOC | E5: 1 A 5 DOC | F5: DETAL | H5: PLANCHA | I5: 1000 | K5: +5 DOC | L5: 1 A 5 DOC | M5: DETAL
A6: DISEÑO | B6: 2000 | D6: =D11 -> 51504 | E6: =E11 -> 62160 | F6: =F11 -> 70684.8 | H6: DISEÑO | I6: 2000 | K6: =K11 -> 44486 | L6: =L11 -> 53690 | M6: =M11 -> 61053.2
A7: CORTE DEL PLOTTER | B7: 200 | D7: =D6/F2 -> 13.553684 | E7: =E6/F2 -> 16.357895 | F7: =F6/F2 -> 18.601263 | H7: CORTE DEL PLOTTER | I7: 200 | K7: =K6/M2 -> 11.706842 | L7: =L6/M2 -> 14.128947 | M7: =M6/M2 -> 16.066632
A8: DEPILADA | B8: 500 | H8: DEPILADA | I8: 500
A9: VINIL | B9: 6000 | H9: ETIQUETA | I9: 200
A10: BOLSA | B10: 100 | D10: 0.4 | E10: 0.6 | F10: 0.9 | H10: BOLSA | I10: 100 | K10: 0.4 | L10: 0.6 | M10: 0.9
A11: HILO | B11: 300 | D11: =B14*1.45 -> 51504 | E11: =B14*1.75 -> 62160 | F11: =B14*1.99 -> 70684.8 | H11: HILO | I11: 300 | K11: =I14*1.45 -> 44486 | L11: =I14*1.75 -> 53690 | M11: =I14*1.99 -> 61053.2
A12: MARQUILLA | B12: 0 | D12: =D11/F2 -> 13.553684 | E12: =E11/F2 -> 16.357895 | F12: =F11/F2 -> 18.601263 | H12: VINIL | I12: 4000 | K12: =K11/M2 -> 11.706842 | L12: =L11/M2 -> 14.128947 | M12: =M11/M2 -> 16.066632
A13: GASTOS OPERATIVOS | B13: 4000 | H13: GASTOS OPERATIVOS | I13: 4000
B14: =SUM(B2:B13) -> 35520 | I14: =SUM(I2:I13) -> 30680
A19: SUETER SIN GORRO | D19: CABALLERO EN BLANCO
A20: TELA DE MONO | B20: =1.2*4*F2 -> 18240
A21: CORTE | B21: 700
A22: COSTURA | B22: 4000 | E22: CABALLERO
A23: PLANCHA | B23: 1000 | D23: +5 DOC | E23: 1 A 5 DOC | F23: DETAL
A24: DISEÑO | B24: 2000 | D24: =D30 -> 55158 | E24: =E30 -> 66570 | F24: =F30 -> 75699.6
A25: CORTE DEL PLOTTER | B25: 200 | D25: =D24/F2 -> 14.515263 | E25: =E24/F2 -> 17.518421 | F25: =F24/F2 -> 19.920947
A26: VINIL | B26: 6000
A27: DEPILADA | B27: 500
A28: ETIQUETA | B28: 200
A29: BOLSA | B29: 100 | D29: 0.4 | E29: 0.6 | F29: 0.9
A30: HILO | B30: 350 | D30: =B33*1.45 -> 55158 | E30: =B33*1.75 -> 66570 | F30: =B33*1.99 -> 75699.6
A31: MARQUILLA | B31: 750 | D31: =D30/F2 -> 14.515263 | E31: =E30/F2 -> 17.518421 | F31: =F30/F2 -> 19.920947
A32: GASTOS OPERATIVOS | B32: 4000
B33: =SUM(B20:B32) -> 38040
A40: SUETER DAMA | C40: DAMA CON VINIL PQÑO | H40: SUETER | J40: NIÑO CON VINIL PQÑO
A41: TELA DE MONO | B41: =B2 -> 16720 | F41: 3800 | H41: TELA DE MONO | I41: =I2 -> 13680
A42: CORTE | B42: 500 | H42: CORTE | I42: 500
A43: COSTURA | B43: 3000 | H43: COSTURA | I43: 3000
A44: PLANCHA | B44: 500 | H44: PLANCHA | I44: 500
A45: VINIL | B45: 3000 | H45: VINIL | I45: 3000
A46: CORDON | B46: 1000 | D46: +5 DOC | E46: 1 A 5 DOC | F46: DETAL | H46: CORDON | I46: 1000 | K46: +5 DOC | L46: 1 A 5 DOC | M46: DETAL
A47: CORTE DEL PLOTTER | B47: 200 | D47: =D52 -> 11.626711 | E47: =E52 -> 14.032237 | F47: =F52 -> 15.956658 | H47: CORTE DEL PLOTTER | I47: 200 | K47: =K52 -> 10.466711 | L47: =L52 -> 12.632237 | M47: =M52 -> 14.364658
A48: DEPILADA | B48: 200 | D48: =D47/F2 -> 0.0030596607 | E48: =E47/F2 -> 0.0036926939 | F48: =F47/F2 -> 0.0041991205 | H48: DEPILADA | I48: 200 | K48: =K47/M2 -> 0.0027543975 | L48: =L47/M2 -> 0.0033242729 | M48: =M47/M2 -> 0.0037801731
A49: ETIQUETA | B49: 200 | H49: ETIQUETA | I49: 200
A50: BOLSA | B50: 100 | H50: BOLSA | I50: 100
...

Sheet BUZO
B1: MUSELINA | E1: VINIL PÑO | I1: MUSELINA | K1: TODO SUBLIMADO | P1: LICRA | R1: COLORES | W1: LICRA | X1: sublimacion total | AD1: MICRO | AF1: VINIL PÑO | AK1: MICRO | AL1: TODO SUBLIMADO | AR1: ALGODÓN
B2: BUZO DAMA | I2: BUZO DAMA | P2: BUZO DAMA | S2: VINIL PÑO | W2: BUZO DAMA | AD2: BUZO DAMA | AK2: BUZO DAMA | AR2: BUZO DAMA
B3: TELA | C3: =0.9*1.8*F3 -> 6480 | F3: 4000 | I3: TELA | J3: =1.1*1.6*F3 -> 7040 | P3: TELA | Q3: =0.9*4*F3 -> 14400 | W3: TELA | X3: =1.2*4*F3 -> 19200 | AD3: TELA | AE3: =1*2.3*F3 -> 9200 | AK3: TELA | AL3: =1*3*F3 -> 12000 | AR3: TELA | AS3: =1*5.31*F3 -> 21240
B4: CORTE | C4: 500 | I4: CORTE | J4: 700 | P4: CORTE | Q4: 700 | W4: CORTE | X4: 700 | AD4: CORTE | AE4: 500 | AK4: CORTE | AL4: 700 | AR4: CORTE | AS4: 700
B5: COSTURA | C5: 2000 | E5: BUZO REPLICA | I5: COSTURA | J5: 2500 | K5: +5 DOC | L5: 1 A 5 DOC | M5: DETAL | P5: COSTURA | Q5: 2500 | W5: COSTURA | X5: 2500 | AD5: COSTURA | AE5: 2500 | AK5: COSTURA | AL5: 2500 | AR5: COSTURA | AS5: 2500
B6: VINIL | C6: 500 | D6: +5 DOC | E6: 1 A 5 DOC | F6: DETAL | I6: PLANCHA | J6: 2000 | K6: =K12 -> 11.704 | L6: =L12 -> 14.63 | M6: =M12 -> 16.6364 | P6: VINIL | Q6: 5000 | S6: BUZO LICRA DAMA | W6: PLANCHA | X6: 3000 | AD6: VINIL | AE6: 1000 | AK6: SUBIMACION | AL6: =15000/1.3 -> 11538.462 | AR6: PLANCHA | AS6: 1000
B7: PLANCHA | C7: 500 | D7: =D11 -> 4.814 | E7: =E11 -> 5.81 | F7: =F11 -> 6.6068 | I7: SUBLIMACION | J7: =1.3*11000 -> 14300 | P7: PLANCHA | Q7: 500 | R7: +5 DOC | S7: 1 A 5 DOC | T7: DETAL | W7: SUBLIMACION | X7: =15000/1.1 -> 13636.364 | Y7: +5 DOC | Z7: 1 A 5 DOC | AA7: DETAL | AD7: PLANCHA | AE7: 500 | AF7: +5 DOC | AG7: 1 A 5 DOC | AH7: DETAL | AK7: PLANCHA | AL7: 3000 | AM7: +5 DOC | AN7: 1 A 5 DOC | AO7: DETAL | AR7: VINIL 15 CMS | AS7: 1500 | AT7: +5 DOC | AU7: 1 A 5 DOC | AV7: DETAL
B8: DISEÑO | C8: 0 | I8: DISEÑO | J8: 1000 | P8: DISEÑO | Q8: 0 | R8: =R12 -> 10.385625 | S8: =S12 -> 11.818125 | T8: =T12 -> 15.04125 | W8: DISEÑO | X8: 2000 | Y8: =Y13 -> 16.833182 | Z8: =Z13 -> 20.315909 | AA8: =AA13 -> 23.102091 | AD8: DISEÑO | AE8: 0 | AF8: =AF13 -> 5.8 | AG8: =AG13 -> 6.6 | AH8: =AH13 -> 7.96 | AK8: VINIL | AL8: 0 | AM8: =AM12 -> 13.462692 | AN8: =AN12 -> 16.248077 | AO8: =AO12 -> 18.476385 | AR8: DISEÑO | AS8: =X8 -> 2000 | AT8: =AT13 -> 12.44825 | AU8: =AU13 -> 15.02375 | AV8: =AV13 -> 17.08415
B9: CORTE DEL PLOTTER | C9: 200 | I9: CORTE DEL PLOTTER | J9: 300 | P9: CORTE DEL PLOTTER | Q9: 200 | W9: CORTE DEL PLOTTER | X9: 0 | AD9: CORTE DEL PLOTTER | AE9: 0 | AK9: DISEÑO | AL9: 2000 | AR9: CORTE DEL PLOTTER | AS9: =X9 -> 0
B10: DEPILADA | C10: 50 | D10: 0.4 | E10: 0.6 | F10: 0.9 | I10: DEPILADA | J10: 200 | P10: DEPILADA | Q10: 200 | W10: DEPILADA | X10: 0 | AD10: DEPILADA | AE10: 0 | AK10: CORTE DEL PLOTTER | AL10: 0 | AR10: DEPILADA | AS10: =X10 -> 0
B11: ETIQUETA | C11: 200 | D11: =C16*1.45 -> 4.814 | E11: =C16*1.75 -> 5.81 | F11: =C16*1.99 -> 6.6068 | I11: ETIQUETA | J11: 200 | K11: 0.4 | L11: 0.6 | M11: 0.9 | P11: ETIQUETA | Q11: 200 | R11: 0.4 | S11: 0.6 | T11: 0.9 | W11: ETIQUETA | X11: 200 | AD11: ETIQUETA | AE11: 0 | AK11: DEPILADA | AL11: 0 | AM11: 0.4 | AN11: 0.6 | AO11: 0.9 | AR11: ETIQUETA | AS11: 200
B12: BOLSA | C12: 100 | I12: BOLSA | J12: 100 | K12: =J16*1.4 -> 11.704 | L12: =J16*1.75 -> 14.63 | M12: =J16*1.99 -> 16.6364 | P12: BOLSA | Q12: 100 | R12: =Q16*1.45 -> 10.385625 | S12: =Q16*1.65 -> 11.818125 | T12: =Q16*2.1 -> 15.04125 | W12: BOLSA | X12: 100 | Y12: 0.4 | Z12: 0.6 | AA12: 0.9 | AD12: BOLSA | AE12: 0 | AF12: 0.4 | AG12: 0.6 | AH12: 0.9 | AK12: ETIQUETA | AL12: 200 | AM12: =AL17*1.45 -> 13.462692 | AN12: =AL17*1.75 -> 16.248077 | AO12: =AL17*1.99 -> 18.476385 | AR12: BOLSA | AS12: 100 | AT12: 0.4 | AU12: 0.6 | AV12: 0.9
B13: HILO | C13: 250 | I13: HILO | J13: 350 | P13: HILO | Q13: 350 | W13: HILO | X13: =J13 -> 350 | Y13: =X16*1.45 -> 16.833182 | Z13: =X16*1.75 -> 20.315909 | AA13: =X16*1.99 -> 23.102091 | AD13: HILO | AE13: =C13 -> 250 | AF13: =AE16*1.45 -> 5.8 | AG13: =AE16*1.65 -> 6.6 | AH13: =AE16*1.99 -> 7.96 | AK13: BOLSA | AL13: 100 | AR13: HILO | AS13: =X13 -> 350 | AT13: =AS16*1.45 -> 12.44825 | AU13: =AS16*1.75 -> 15.02375 | AV13: =AS16*1.99 -> 17.08415
B14: MARQUILLA | C14: 500 | I14: MARQUILLA | J14: 750 | P14: MARQUILLA | Q14: 500 | W14: MARQUILLA | X14: =J14 -> 750 | AD14: MARQUILLA | AE14: 50 | AK14: HILO | AL14: 350 | AR14: MARQUILLA | AS14: =X14 -> 750
B15: GASTOS OPERATIVOS | C15: 2000 | I15: GASTOS OPERATIVOS | J15: 4000 | P15: GASTOS OPERATIVOS | Q15: 4000 | W15: GASTOS OPERATIVOS | X15: =J15 -> 4000 | AD15: GASTOS OPERATIVOS | AE15: =C15 -> 2000 | AK15: MARQUILLA | AL15: 750 | AR15: GASTOS OPERATIVOS | AS15: =X15 -> 4000
C16: =SUM(C3:C15)/F3 -> 3.32 | J16: =SUM(J3:J15)/F3 -> 8.36 | Q16: =SUM(Q3:Q15)/F3 -> 7.1625 | X16: =SUM(X3:X15)/F3 -> 11.609091 | AE16: =SUM(AE3:AE15)/F3 -> 4 | AK16: GASTOS OPERATIVOS | AL16: 4000 | AS16: =SUM(AS3:AS15)/F3 -> 8.585
AL17: =SUM(AL3:AL16)/F3 -> 9.2846154
B20: MUSELINA | E20: VINIL PÑO | I20: MUSELINA | K20: TODO SUBLIMADO | P20: LICRA | R20: COLORES | W20: LICRA | X20: sublimacion total | AD20: MICRO | AF20: VINIL PÑO | AK20: MICRO | AM20: TODO SUBLIMADO
B21: BUZO NIÑO | I21: BUZO NIÑO | P21: BUZO NIÑO | S21: NIÑOS PÑO | W21: BUZO NIÑO | AD21: BUZO NIÑO | AK21: BUZO NIÑO
B22: TELA | C22: =0.7*1.6*F22 -> 4256 | F22: 3800 | I22: TELA | J22: =0.8*1.2*F3 -> 3840 | P22: TELA | Q22: =0.9*4*F3 -> 14400 | W22: TELA | X22: =0.5*4*F3/1.5 -> 5333.3333 | AD22: TELA | AE22: =0.85*3*F22 -> 9690 | AK22: TELA | AL22: =0.7*2*F22 -> 5320
B23: CORTE | C23: 500 | I23: CORTE | J23: 700 | P23: CORTE | Q23: 700 | S23: VINIL PÑO | W23: CORTE | X23: 700 | AD23: CORTE | AE23: 700 | AK23: CORTE | AL23: 700
B24: COSTURA | C24: 2000 | I24: COSTURA | J24: 2500 | P24: COSTURA | Q24: 2500 | W24: COSTURA | X24: 2500 | AD24: COSTURA | AE24: 2500 | AK24: COSTURA | AL24: 2500
B25: VINIL | C25: 500 | D25: +5 DOC | E25: 1 A 5 DOC | F25: DETAL | I25: SUBLIMACION | J25: =0.8*13000 -> 10400 | K25: +5 DOC | L25: 1 A 5 DOC | M25: DETAL | P25: VINIL | Q25: 2000 | S25: BUZO LICRA NIÑO | W25: SUBIMACION | X25: =0.5*10000 -> 5000 | AD25: VINIL | AE25: 500 | AK25: SUBLIMACION TOTAL | AL25: =0.7*10000 -> 7000
B26: PLANCHA | C26: 500 | D26: =D30 -> 4.0078 | E26: =E30 -> 4.837 | F26: =F30 -> 5.50036 | I26: PLANCHA | J26: 3000 | K26: =K30 -> 9.928875 | L26: =L30 -> 11.983125 | M26: =M30 -> 13.626525 | P26: PLANCHA | Q26: 0 | R26: +5 DOC | S26: 1 A 5 DOC | T26: DETAL | W26: PLANCHA | X26: 2000 | Y26: +5 DOC | Z26: 1 A 5 DOC | AA26: DETAL | AD26: PLANCHA | AE26: 1000 | AF26: +5 DOC | AG26: 1 A 5 DOC | AH26: DETAL | AK26: PLANCHA | AL26: 1000 | AM26: +5 DOC | AN26: 1 A 5 DOC | AO26: DETAL
B27: DISEÑO | C27: 0 | I27: DISEÑO | J27: 2000 | P27: DISEÑO | Q27: 1000 | R27: =R31 -> 9.38875 | S27: =S31 -> 11.0075 | T27: =T31 -> 13.5975 | W27: VINIL | X27: 0 | Y27: =Y32 -> 7.2802083 | Z27: =Z32 -> 8.7864583 | AA27: =AA32 -> 9.9914583 | AD27: DISEÑO | AE27: 0 | AF27: =AF32 -> 6.412625 | AG27: =AG32 -> 7.739375 | AH27: =AH32 -> 8.800775 | AK27: DISEÑO | AL27: 1000 | AM27: =AM31 -> 8.1635 | AN27: =AN31 -> 9.008 | AO27: =AO31 -> 11.2037
B28: CORTE DEL PLOTTER | C28: 200 | I28: CORTE DEL PLOTTER | J28: 200 | P28: CORTE DEL PLOTTER | Q28: 200 | W28: DISEÑO | X28: 0 | AD28: CORTE DEL PLOTTER | AE28: =C28 -> 200 | AK28: CORTE DEL PLOTTER | AL28: 0
B29: DEPILADA | C29: 50 | D29: 0.4 | E29: 0.6 | F29: 0.9 | I29: DEPILADA | J29: 200 | K29: 0.4 | L29: 0.6 | M29: 0.9 | P29: DEPILADA | Q29: 200 | W29: CORTE DEL PLOTTER | X29: 0 | AD29: DEPILADA | AE29: =C29 -> 50 | AK29: DEPILADA | AL29: 0
B30: ETIQUETA | C30: 200 | D30: =C35*1.45 -> 4.0078 | E30: =C35*1.75 -> 4.837 | F30: =C35*1.99 -> 5.50036 | I30: ETIQUETA | J30: 200 | K30: =J35*1.45 -> 9.928875 | L30: =J35*1.75 -> 11.983125 | M30: =J35*1.99 -> 13.626525 | P30: ETIQUETA | Q30: 200 | R30: 0.4 | S30: 0.6 | T30: 0.9 | W30: DEPILADA | X30: 0 | AD30: ETIQUETA | AE30: 200 | AK30: ETIQUETA | AL30: 200 | AM30: 0.4 | AN30: 0.6 | AO30: 0.9
B31: BOLSA | C31: 100 | I31: BOLSA | J31: 100 | P31: BOLSA | Q31: 100 | R31: =Q35*1.45 -> 9.38875 | S31: =Q35*1.7 -> 11.0075 | T31: =Q35*2.1 -> 13.5975 | W31: ETIQUETA | X31: 200 | Y31: 0.4 | Z31: 0.6 | AA31: 0.9 | AD31: BOLSA | AE31: 100 | AF31: 0.4 | AG31: 0.6 | AH31: 0.9 | AK31: BOLSA | AL31: 100 | AM31: =AL35*1.45 -> 8.1635 | AN31: =AL35*1.6 -> 9.008 | AO31: =AL35*1.99 -> 11.2037
B32: HILO | C32: 250 | I32: HILO | J32: 250 | P32: HILO | Q32: 100 | W32: BOLSA | X32: 0 | Y32: =X36*1.45 -> 7.2802083 | Z32: =X36*1.75 -> 8.7864583 | AA32: =X36*1.99 -> 9.9914583 | AD32: HILO | AE32: =C32 -> 250 | AF32: =AE35*1.45 -> 6.412625 | AG32: =AE35*1.75 -> 7.739375 | AH32: =AE35*1.99 -> 8.800775 | AK32: HILO | AL32: 250
B33: MARQUILLA | C33: 500 | I33: MARQUILLA | J33: 0 | P33: MARQUILLA | Q33: 500 | W33: HILO | X33: 350 | AD33: MARQUILLA | AE33: 500 | AK33: MARQUILLA | AL33: 750
B34: GASTOS OPERATIVOS | C34: 2000 | I34: GASTOS OPERATIVOS | J34: 4000 | P34: GASTOS OPERATIVOS | Q34: 4000 | W34: MARQUILLA | X34: 0 | AD34: GASTOS OPERATIVOS | AE34: =C34 -> 2000 | AK34: GASTOS OPERATIVOS | AL34: 3700
C35: =SUM(C22:C34)/F3 -> 2.764 | J35: =SUM(J22:J34)/F3 -> 6.8475 | Q35: =SUM(Q22:Q34)/F3 -> 6.475 | W35: GASTOS OPERATIVOS | X35: 4000 | AE35: =SUM(AE22:AE34)/F3 -> 4.4225 | AL35: =SUM(AL22:AL34)/F3 -> 5.63
X36: =SUM(X22:X35)/F3 -> 5.0208333
B39: MUSELINA | I39: MUSELINA | K39: TODO SUBLIMADO | P39: LICRA | R39: COLORES | W39: LICRA | X39: sublimacion total | AD39: MICRO | AF39: VINIL PÑO | AK39: MICRO | AL39: TODO SUBLIMADO | AR39: ALGODÓN | AY39: ALGODÓN
B40: BUZO CABALLERO | E40: VINIL PÑO | I40: BUZO CABALLERO | P40: BUZO | R40: CABALLERO | W40: BUZO CABALLERO | AD40: BUZO CABALLERO | AK40: BUZO CABALLERO | AR40: BUZO CABALLERO | AY40: BUZO CABALLERO
B41: TELA | C41: =2*1.3*F3 -> 10400 | I41: TELA | J41: =1.5*1.2*4000 -> 7200 | P41: TELA | Q41: =1.5*1*F3 -> 6000 | W41: TELA | X41: =2*6*F3 -> 48000 | AD41: TELA | AE41: =1.5*2*F3 -> 12000 | AK41: TELA | AL41: =1.5*2*F3 -> 12000 | AR41: TELA | AS41: =1.5*5.31*F3 -> 31860 | AY41: TELA | AZ41: =1.5*5.31*F3 -> 31860
B42: CORTE | C42: 700 | I42: CORTE | J42: 1000 | K42: +5 DOC | L42: 1 A 5 DOC | M42: DETAL | P42: CORTE | Q42: 1400 | S42: VINIL PÑO | W42: CORTE | X42: 1500 | AD42: CORTE | AE42: 700 | AK42: CORTE | AL42: 700 | AR42: CORTE | AS42: 700 | AY42: CORTE | AZ42: 700
B43: COSTURA | C43: 3500 | I43: COSTURA | J43: 4500 | K43: =K48 -> 13.25625 | L43: =L48 -> 15.02375 | M43: =M48 -> 17.586625 | P43: COSTURA | Q43: 4500 | W43: COSTURA | X43: 8000 | AD43: COSTURA | AE43: 3500 | AK43: COSTURA | AL43: 3500 | AR43: COSTURA | AS43: 2500 | AY43: COSTURA | AZ43: 2500 | BA43: +5 DOC | BB43: 1 A 5 DOC | BC43: DETAL
B44: VINIL | C44: 1500 | D44: +5 DOC | E44: 1 A 5 DOC | F44: DETAL | I44: PLANCHA | J44: 2000 | P44: VINIL | Q44: 4500 | W44: PLANCHA | X44: 5000 | AD44: PLANCHA | AE44: 1000 | AK44: SUBIMACION | AL44: =1.5*11000 -> 16500 | AR44: PLANCHA | AS44: 0 | AY44: PLANCHA | AZ44: 1000 | BA44: =BA49 -> 16.0805 | BB44: =BB49 -> 19.4075 | BC44: =BC49 -> 22.0691
...

Sheet FALDA SHORT LICRA
A2: FALDA SHORT | C2: VINIL PÑO
A3: DAMA LICRA
A4: TELA | B4: =1.5*5*4000 -> 30000
A5: CORTE | B5: 700
A6: COSTURA | B6: 5000
A7: PLANCHA | B7: 1000
A8: VINIL | B8: 500 | C8: +5 DOC | D8: 1 A 5 DOC | E8: DETAL
A9: DISEÑO | B9: 500 | C9: =C15 -> 15.05 | D9: =D15 -> 18.8125 | E9: =E15 -> 20.425
A10: CORTE DEL PLOTTER | B10: 500
A11: DEPILADA | B11: 50
A12: ETIQUETA | B12: 200
A13: BOLSA | B13: 100
A14: HILO | B14: =250 -> 250 | C14: 0.4 | D14: 0.6 | E14: 0.9
A15: MARQUILLA | B15: 500 | C15: =B17*1.4 -> 15.05 | D15: =B17*1.75 -> 18.8125 | E15: =B17*1.9 -> 20.425
A16: GASTOS OPERATIVOS | B16: 3700
B17: =SUM(B4:B16)/4000 -> 10.75 | C17: =C15-B17 -> 4.3

Sheet CROPTOP LICRA
A2: CROP TOP | D2: VINIL PÑO
A3: LICRA DAMA
A4: TELA | B4: =0.6*5*4000 -> 12000
A5: CORTE | B5: 700
A6: COSTURA | B6: 3500
A7: PLANCHA | B7: 1000
A8: VINIL | B8: 500 | D8: +5 DOC | E8: 1 A 5 DOC | F8: DETAL
A9: DISEÑO | B9: 1000 | D9: =D15 -> 8.47 | E9: =E15 -> 10.5875 | F9: =F15 -> 12.0395
A10: CORTE DEL PLOTTER | B10: 500
A11: DEPILADA | B11: 250
A12: ETIQUETA | B12: 200
A13: BOLSA | B13: 100
A14: HILO | B14: =250 -> 250 | D14: 0.4 | E14: 0.6 | F14: 0.9
A15: MARQUILLA | B15: 500 | D15: =B17*1.4 -> 8.47 | E15: =B17*1.75 -> 10.5875 | F15: =B17*1.99 -> 12.0395
A16: GASTOS OPERATIVOS | B16: 3700
B17: =SUM(B4:B16)/4000 -> 6.05

Sheet MANUBRIO
A2: MANUBRIO | E2: MANUBRIO | H2: MANUBRIO
A3: PEQUEÑO | B3: 510 | E3: MEDIANO | F3: 40 | H3: GRANDE | I3: 65
A4: TELA TRANSPARENTE | B4: =27*2.3 -> 62.1 | E4: TELA TRANSPARENTE | F4: =2.3*3 -> 6.9 | H4: TELA TRANSPARENTE | I4: =2.3*4.5 -> 10.35
A5: TELA LONA | B5: =25*2.75 -> 68.75 | E5: TELA LONA | F5: =2.75*3 -> 8.25 | H5: TELA LONA | I5: =2.75*4 -> 11
A6: COSTURA | B6: =510*2000/4000 -> 255 | E6: COSTURA | F6: =40*2000/4000 -> 20 | H6: COSTURA | I6: =65*2000/4000 -> 32.5
A7: PLANCHA | B7: 25 | E7: PLANCHA | F7: 2 | H7: PLANCHA | I7: 4
A8: CORTE | B8: =510*500/4000 -> 63.75 | E8: CORTE | F8: =40*500/4000 -> 5 | H8: CORTE | I8: =65*500/4000 -> 8.125
A9: HILO | B9: 20 | E9: HILO | F9: 5 | H9: HILO | I9: 5
A10: CIERRE MAGICO | B10: =1500*286/4000 -> 107.25 | E10: CIERRE MAGICO | F10: =1500*28/4000 -> 10.5 | H10: CIERRE MAGICO | I10: =1500*47/4000 -> 17.625
A11: IMPRESIÓN | B11: =27*10000/4000 -> 67.5 | E11: IMPRESIÓN | F11: =3*10000/4000 -> 7.5 | H11: IMPRESIÓN | I11: =4*10000/4000 -> 10
A12: GASTOS OPERATIVOS | B12: =1700/4000*510 -> 216.75 | E12: GASTOS OPERATIVOS | F12: =1700/4000*40 -> 17 | H12: GASTOS OPERATIVOS | I12: =1700/4000*65 -> 27.625
B13: =SUM(B4:B12) -> 886.1 | F13: =SUM(F4:F12) -> 82.15 | I13: =SUM(I4:I12) -> 126.225
B14: =B13/510 -> 1.737451 | F14: =F13/40 -> 2.05375 | I14: =I13/65 -> 1.9419231
E17: =B13+F13+I13 -> 1094.475
E18: =1120/615 -> 1.8211382 | F18: =E18*1.5 -> 2.7317073

Sheet ESTANDARTE 
A2: MUSE/ATLE
A3: SHORT NIÑO | F3: 3800
A4: TELA | B4: =1.4*2*F3 -> 10640
A5: CORTE | B5: 700
A6: COSTURA | B6: 3000
A7: SUBLIMACION | B7: =15000*1.4 -> 21000
A8: TUBO | B8: 8000 | D8: =B18*1.75 -> 22.330921
B9: 0
B10: 0
B11: 0
B12: 0
A13: ETIQUETA | B13: 250
A14: BOLSA | B14: 100
A15: HILO | B15: 350
A16: MARQUILLA | B16: 750
A17: GASTOS OPERATIVOS | B17: 3700
B18: =SUM(B4:B17)/F3 -> 12.760526

Sheet SHORT
A1: MUSE/ATLE | D1: EN BLANCO
A2: SHORT NIÑO | F2: 3800 | G2: DÓLAR
A3: TELA | B3: =0.55*1.8*F2 -> 3762
A4: CORTE | B4: 500
A5: COSTURA | B5: 2000
A6: MALLA | B6: 800
A7: CAUCHO | B7: 800
A8: PLANCHA | B8: 0 | D8: +5 DOC | E8: 1 A 5 DOC | F8: DETAL
A9: DISEÑO | B9: 0 | D9: =D12 -> 4.1675789 | E9: =E12 -> 4.7629474 | F9: =F12 -> 5.656
A10: CORTE DEL PLOTTER | B10: 0
A11: DEPILADA | B11: 0 | D11: 0.4 | E11: 0.6 | F11: 0.9
A12: ETIQUETA | B12: 250 | D12: =B17*1.4 -> 4.1675789 | E12: =B17*1.6 -> 4.7629474 | F12: =B17*1.9 -> 5.656
A13: BOLSA | B13: 100
A14: HILO | B14: 350
A15: MARQUILLA | B15: 750
A16: GASTOS OPERATIVOS | B16: 2000
B17: =SUM(B3:B16)/F2 -> 2.9768421
A21: SHORT DAMA
A22: TELA | B22: =0.6*6/2*F2 -> 6840
A23: CORTE | B23: 700
A24: COSTURA | B24: 2500
A25: MALLA | B25: 0
A26: CAUCHO | B26: 0
A27: PLANCHA | B27: 2000 | D27: +5 DOC | E27: 1 A 5 DOC | F27: DETAL
A28: DISEÑO | B28: 7000 | D28: =D32 -> 8.3226316 | E28: =E32 -> 10.106053 | F28: =F32 -> 11.295
A29: CORTE DEL PLOTTER | B29: 0
A30: DEPILADA | B30: 0
A31: ETIQUETA | B31: 50 | D31: 0.4 | E31: 0.6 | F31: 0.9
A32: BOLSA | B32: 100 | D32: =B36*1.4 -> 8.3226316 | E32: =B36*1.7 -> 10.106053 | F32: =B36*1.9 -> 11.295
A33: HILO | B33: 350
A34: MARQUILLA | B34: 50
A35: GASTOS OPERATIVOS | B35: 3000
B36: =SUM(B22:B35)/F2 -> 5.9447368
D42: EN BLANCO
A43: MUSE/ATLE
A44: SHORT CABALLERO
A45: TELA | B45: =0.8*1.8*F2 -> 5472
A46: CORTE | B46: 500
A47: COSTURA | B47: 1500
A48: MALLA | B48: 0 | D48: +5 DOC | E48: 1 A 5 DOC | F48: DETAL
...

Sheet CV TASLAN
F2: TASLAN | AC2: TASLAN
A3: CORTA VIENTO DAMA | D3: CON VINIL PÑO | X3: CORTA VIENTO DAMA | AA3: SUBLIMACION TOTAL
A4: TELA TASLAN | B4: =1.5*5*F4 -> 28500 | F4: 3800 | G4: DÓLAR | X4: TELA TASLAN | Y4: =1.5*3*AC4 -> 17550 | AC4: 3900 | AD4: DÓLAR
A5: CORTE | B5: 700 | K5: Mts | L5: $ | X5: CORTE | Y5: 700
A6: COSTURA | B6: 9000 | I6: TELA DAMA 3 DOC | J6: 1,5S 1,5L | K6: =36*1.6 -> 57.6 | X6: COSTURA | Y6: 4500
A7: CIERRE | B7: 4000 | I7: TELA caballero 6 DOC | J7: 3 M 3 L | K7: =6*12*1.9 -> 136.8 | X7: CIERRE | Y7: 3000
A8: PLANCHA | B8: 500 | D8: CORTA VIENTO DE DAMA IMPERMEABLE | I8: TELA caballero 1 DOC | J8: 1 XL | K8: =12*2.2 -> 26.4 | X8: PLANCHA | Y8: 500 | AA8: CORTA VIENTO DE DAMA IMPERMEABLE
A9: VINIL 15 CMS | B9: 5500 | K9: =SUM(K6:K8) -> 220.8 | L9: =K9*3 -> 662.4 | O9: =120*13 -> 1560 | X9: SUBLIMACION TOTAL | Y9: 15000
A10: DISEÑO | B10: 1000 | D10: +5 DOC | E10: 1 A 5 DOC | F10: DETAL | X10: DISEÑO | Y10: 2000 | AA10: +5 DOC | AB10: 1 A 5 DOC | AC10: DETAL
A11: CORTE DEL PLOTTER | B11: 500 | D11: =D15 -> 21.005921 | E11: =E15 -> 25.351974 | F11: =F15 -> 28.828816 | I11: Cierres | J11: 120 | K11: =2500/4000 -> 0.625 | L11: =K11*J11 -> 75 | X11: ETIQUETA | Y11: 0 | AA11: =AA15 -> 17.883333 | AB11: =AB15 -> 21.583333 | AC11: =AC15 -> 24.543333
A12: DEPILADA | B12: 500 | I12: vinil | J12: 120 | K12: =2000/4000 -> 0.5 | L12: =K12*J12 -> 60 | X12: BOLSA | Y12: 0
A13: ETIQUETA | B13: 0 | I13: costura | J13: =120 -> 120 | K13: 1 | L13: =J13*K13 -> 120 | X13: HILO | Y13: 350
A14: BOLSA | B14: 0 | D14: 0.35 | E14: 0.5 | F14: 0.8 | I14: depilada | J14: 120 | K14: =440/4000 -> 0.11 | L14: =J14*K14 -> 13.2 | N14: =0.11*4000 -> 440 | X14: MARQUILLA | Y14: 500 | AA14: 0.45 | AB14: 0.75 | AC14: 0.99
A15: HILO | B15: 350 | D15: =B18*1.45 -> 21.005921 | E15: =B18*1.75 -> 25.351974 | F15: =B18*1.99 -> 28.828816 | I15: etiqueta | J15: 120 | K15: =200/4000 -> 0.05 | L15: =J15*K15 -> 6 | X15: GASTOS OPERATIVOS | Y15: 4000 | AA15: =Y16*1.45 -> 17.883333 | AB15: =Y16*1.75 -> 21.583333 | AC15: =Y16*1.99 -> 24.543333
A16: MARQUILLA | B16: 500 | I16: corte plotter | J16: 120 | K16: =300/4000 -> 0.075 | L16: =J16*K16 -> 9 | Y16: =SUM(Y4:Y15)/AC4 -> 12.333333
A17: GASTOS OPERATIVOS | B17: 4000 | I17: diseño | J17: 120 | K17: =1000/4000 -> 0.25 | L17: =J17*K17 -> 30
B18: =SUM(B4:B17)/F4 -> 14.486842 | I18: marquilla | J18: 120 | K18: =500/4000 -> 0.125 | L18: =J18*K18 -> 15
I19: corte tela | J19: 120 | K19: =1400/4000 -> 0.35 | L19: =J19*K19 -> 42
L20: =SUM(L9:L19) -> 1032.6
L21: =L20*1.55 -> 1600.53 | M21: =L21/120 -> 13.33775 | N21: =M21*4000 -> 53351
L22: =L21-L20 -> 567.93 | M22: Ganancia
A24: CORTA VIENTO CABALLERO | D24: CON VINIL PÑO | I24: CORTA VIENTO CABALLERO | L24: CON VINIL PÑO | P24: PANTALON DE MONO | S24: CON VINIL PÑO | X24: CORTA VIENTO CABALLERO | AA24: SUBLIMACION TOTAL
A25: TELA TASLAN | B25: =2.2*2.5*F4 -> 20900 | I25: TELA TASLAN | J25: =1.8*3*F4 -> 20520 | P25: TELA TASLAN | Q25: =1.1*3*F4 -> 12540 | X25: TELA TASLAN | Y25: =2.5*3*AC4 -> 29250
A26: CORTE | B26: 700 | I26: CORTE | J26: 700 | P26: CORTE | Q26: =J26 -> 700 | X26: CORTE | Y26: 1500
A27: COSTURA | B27: 5000 | I27: COSTURA | J27: 3500 | P27: COSTURA | Q27: 2500 | X27: COSTURA | Y27: 24000
A28: CIERRE | B28: 1500 | D28: CORTA VIENTO DE CABALLERO IMPERMEABLE | I28: CIERRE | J28: 3500 | L28: CORTA VIENTO DE CABALLERO IMPERMEABLE | P28: CIERRE | Q28: 0 | S28: CORTA VIENTO DE CABALLERO IMPERMEABLE | X28: FORRO | Y28: =2.5*1.3*3700 -> 12025 | AA28: CORTA VIENTO DE CABALLERO IMPERMEABLE
A29: PLANCHA | B29: 1400 | I29: PLANCHA | J29: 2000 | P29: PLANCHA | Q29: 0 | X29: CIERRE | Y29: 1800
A30: VINIL 15 CMS | B30: 4500 | D30: +5 DOC | E30: 1 A 5 DOC | F30: DETAL | I30: SUBLIMACION TOTAL | J30: 0 | L30: +5 DOC | M30: 1 A 5 DOC | N30: DETAL | P30: SUBLIMACION TOTAL | Q30: 0 | S30: +5 DOC | T30: 1 A 5 DOC | U30: DETAL | X30: PLANCHA | Y30: 4000 | AA30: +5 DOC | AB30: 1 A 5 DOC | AC30: DETAL
A31: DISEÑO | B31: 1500 | D31: =D36 -> 15.363158 | E31: =E36 -> 18.106579 | F31: =F36 -> 21.837632 | I31: DISEÑO | J31: 1000 | L31: =L36 -> 12.493684 | M31: =M36 -> 16.818421 | N31: =N36 -> 19.124947 | P31: DISEÑO | Q31: 0 | S31: =S36 -> 6.4452632 | T31: =T36 -> 8.6763158 | U31: =U36 -> 9.8662105 | X31: kalandra | Y31: =1.8*13000 -> 23400 | AA31: =AA34 -> 38.452885 | AB31: =AB34 -> 46.408654 | AC31: =AC34 -> 52.773269
A32: CORTE DEL PLOTTER | B32: 500 | I32: CORTE DEL PLOTTER | J32: 200 | P32: CORTE DEL PLOTTER | Q32: 0 | X32: DISEÑO | Y32: 2000
A33: DEPILADA | B33: 500 | I33: DEPILADA | J33: 200 | P33: DEPILADA | Q33: 0 | X33: ETIQUETA | Y33: 200 | AA33: 0.45 | AB33: 0.75 | AC33: 0.99
A34: ETIQUETA | B34: 250 | I34: ETIQUETA | J34: 50 | P34: ETIQUETA | Q34: 0 | X34: CORDON | Y34: 700 | AA34: =Y38*1.45 -> 38.452885 | AB34: =Y38*1.75 -> 46.408654 | AC34: =Y38*1.99 -> 52.773269
A35: BOLSA | B35: 100 | D35: 0.45 | E35: 0.75 | F35: 0.99 | I35: BOLSA | J35: 150 | L35: 0.4 | M35: 0.65 | N35: 0.9 | P35: BOLSA | Q35: 150 | S35: 0.4 | T35: 0.65 | U35: 0.9 | X35: HILO | Y35: =Y13 -> 350
A36: HILO | B36: =B15 -> 350 | D36: =B39*1.4 -> 15.363158 | E36: =B39*1.65 -> 18.106579 | F36: =B39*1.99 -> 21.837632 | I36: HILO | J36: 200 | L36: =J39*1.3 -> 12.493684 | M36: =J39*1.75 -> 16.818421 | N36: =J39*1.99 -> 19.124947 | P36: HILO | Q36: 200 | S36: =Q39*1.3 -> 6.4452632 | T36: =Q39*1.75 -> 8.6763158 | U36: =Q39*1.99 -> 9.8662105 | X36: MARQUILLA | Y36: 200
A37: MARQUILLA | B37: 500 | I37: MARQUILLA | J37: 500 | P37: MARQUILLA | Q37: 750 | X37: GASTOS OPERATIVOS | Y37: 4000
A38: GASTOS OPERATIVOS | B38: 4000 | I38: GASTOS OPERATIVOS | J38: 4000 | P38: GASTOS OPERATIVOS | Q38: 2000 | Y38: =SUM(Y25:Y37)/AC4 -> 26.519231
B39: =SUM(B25:B38)/F4 -> 10.973684 | J39: =SUM(J25:J38)/F4 -> 9.6105263 | Q39: =SUM(Q25:Q38)/F4 -> 4.9578947
L42: =L36-J39 -> 2.8831579 | P42: =L36+S36 -> 18.938947
L43: =S36-Q39 -> 1.4873684
L44: =SUM(L42:L43)-1.05 -> 3.3205263 | M44: =L44*200 -> 664.10526
...

Sheet MOUSE
A2: MOUSE 5MM
A3: MOUSE | F3: 3800
A4: MOUSE | B4: 10000
A5: SUBLIMACION | B5: =1000 -> 1000 | D5: 45 | E5: 70 | F5: 99
A6: PLANCHA | B6: 1000 | D6: =B9*1.45 -> 5.9907895 | E6: =B9*1.7 -> 7.0236842 | F6: =B9*1.99 -> 8.2218421
A7: DISEÑO | B7: 1000
A8: GASTOS OPERATIVOS | B8: 2700
B9: =SUM(B4:B8)/F3 -> 4.1315789

Sheet PAÑOLETA
A2: DELANTAL
A3: UNISEX | F3: 3800
A4: TELA | B4: =0.7*3 -> 2.1
A5: CORTE | B5: =700/F3 -> 0.18421053 | D5: +5 DOC | E5: 1 A 5 DOC | F5: DETAL
A6: COSTURA | B6: =3000/F3 -> 0.78947368 | D6: =D9 -> 10.345263 | E6: =E9 -> 11.084211 | F6: =F9 -> 14.705053
A7: SUBLIMACION | B7: =13000*0.7/2/F3 -> 1.1973684
A8: PLANCHA | B8: =500/F3 -> 0.13157895 | D8: 45 | E8: 75 | F8: 99
A9: DISEÑO | B9: =1500/F3 -> 0.39473684 | D9: =B14*1.4 -> 10.345263 | E9: =B14*1.5 -> 11.084211 | F9: =B14*1.99 -> 14.705053
A10: CORTE DEL PLOTTER | B10: =500/F3 -> 0.13157895
A11: HERRAJES | B11: =5000/F3 -> 1.3157895
A12: HILO | B12: =350/F3 -> 0.092105263
A13: GASTOS OPERATIVOS | B13: =4000/F3 -> 1.0526316
B14: =SUM(B4:B13) -> 7.3894737
A17: bandana de perro
A18: tela | B18: =1.3*3/8*4400 -> 2145
A19: impresión | B19: =1.3*11000/8 -> 1787.5
A20: planchado | B20: 500
A21: confeccion | B21: 1000 | D21: =B23*1.45 -> 8602.125
A22: diseño | B22: 500
B23: =SUM(B18:B22) -> 5932.5

Sheet PROMO
A1: PRODUCTO | B1: MATERIAL | C1: CANTIDAD | D1: PRECIO | E1: PEDIDO | F1: MONTO
A2: GORRA | B2: MALLA | C2: 1
B3: MALLA | C3: 6 A 12
B4: MALLA | C4: 12 O MAS
A5: GORRA | B5: DRILL | C5: 1
B6: DRILL | C6: 6 A 12
B7: DRILL | C7: 12 O MAS
A8: GORRA | B8: DRILL | C8: 1
B9: DRILL | C9: 6 A 12
B10: DRILL | C10: 12 O MAS
A12: PRODUCTO | B12: MATERIAL | C12: CANTIDAD | D12: PRECIO | E12: PEDIDO | F12: MONTO
A13: FRANELA | B13: MICRO | C13: 1
B14: MICRO | C14: 6 A 12
B15: MICRO | C15: 12 O MAS
A16: FRANELA | B16: MUSELINA | C16: 1
B17: MUSELINA | C17: 6 A 12
B18: MUSELINA | C18: 12 O MAS

Sheet CV MEMORY
A2: CORTA VIENTO DAMA | D2: CON VINIL PÑO | I2: DAMA | L2: SUBLIMADA TODA
A3: TELA MEMORY | B3: =1.8*2*F3 -> 13680 | F3: 3800 | G3: DÓLAR | I3: TELA MEMORY | J3: =1.5*2*N3 -> 11400 | N3: 3800
A4: CORTE | B4: 700 | I4: CORTE | J4: 700
A5: COSTURA | B5: 3500 | I5: COSTURA | J5: 4500
A6: CIERRE | B6: 3000 | I6: CIERRE | J6: 3000
A7: PLANCHA | B7: 1000 | D7: CORTA VIENTO DE DAMA IMPERMEABLE | I7: PLANCHA | J7: 3000 | L7: CORTA VIENTO DE DAMA IMPERMEABLE
A8: VINIL 15 CMS | B8: 1000 | I8: SUBLIMACION TOTAL | J8: 13000
A9: DISEÑO | B9: 0 | D9: +5 DOC | E9: 1 A 5 DOC | F9: DETAL | I9: DISEÑO | J9: 2000 | L9: +5 DOC | M9: 1 A 5 DOC | N9: DETAL
A10: CORTE DEL PLOTTER | B10: 200 | D10: =D14 -> 10.867368 | E10: =E14 -> 13.115789 | F10: =F14 -> 14.914526 | I10: CORTE DEL PLOTTER | J10: 0 | L10: =L14 -> 16.331579 | M10: =M14 -> 19.710526 | N10: =N14 -> 22.413684
A11: DEPILADA | B11: 200 | I11: DEPILADA | J11: 0
A12: ETIQUETA | B12: 250 | I12: ETIQUETA | J12: 250
A13: BOLSA | B13: 100 | D13: 0.35 | E13: 0.5 | F13: 0.8 | I13: BOLSA | J13: 100 | L13: 0.35 | M13: 0.5 | N13: 0.8
A14: HILO | B14: 350 | D14: =B17*1.45 -> 10.867368 | E14: =B17*1.75 -> 13.115789 | F14: =B17*1.99 -> 14.914526 | I14: HILO | J14: 350 | L14: =J17*1.45 -> 16.331579 | M14: =J17*1.75 -> 19.710526 | N14: =J17*1.99 -> 22.413684
A15: MARQUILLA | B15: 500 | I15: MARQUILLA | J15: 500
A16: GASTOS OPERATIVOS | B16: 4000 | I16: GASTOS OPERATIVOS | J16: 4000
B17: =SUM(B3:B16)/F3 -> 7.4947368 | J17: =SUM(J3:J16)/N3 -> 11.263158
A19: CORTA VIENTO NIÑO | D19: CON VINIL PÑO | I19: CORTA VIENTO NIÑO | L19: SUBLIMADA TODA
A20: TELA MEMORY | B20: =1.8*1.2*F20 -> 8640 | F20: 4000 | G20: DÓLAR | I20: TELA MEMORY | J20: =1*4*N20 -> 15200 | N20: 3800 | O20: DÓLAR
A21: CORTE | B21: 500 | I21: CORTE | J21: 700
A22: COSTURA | B22: 3500 | I22: COSTURA | J22: 3500
A23: CIERRE | B23: 1200 | I23: CIERRE | J23: 1300
A24: PLANCHA | B24: =1.6*3500 -> 5600 | D24: CORTA VIENTO DE DAMA IMPERMEABLE | I24: PLANCHA | J24: 3000 | L24: CORTA VIENTO DE DAMA IMPERMEABLE
A25: SUBLIMACION | B25: =1.8*6000 -> 10800 | I25: SUBLIMACION TOTAL | J25: 13000
A26: DISEÑO | B26: 300 | D26: +5 DOC | E26: 1 A 5 DOC | F26: DETAL | I26: DISEÑO | J26: 1000 | L26: +5 DOC | M26: 1 A 5 DOC | N26: DETAL
A27: CORDON | B27: 700 | D27: =D31 -> 12.575125 | E27: =E31 -> 15.176875 | F27: =F31 -> 17.258275 | I27: CORTE DEL PLOTTER | J27: 0 | L27: =L31 -> 15.713158 | M27: =M31 -> 19.641447 | N27: =N31 -> 22.335132
A28: CAUCHO | B28: 500 | I28: DEPILADA | J28: 0
A29: ETIQUETA | B29: 250 | I29: ETIQUETA | J29: 0
A30: BOLSA | B30: 100 | D30: 0.35 | E30: 0.5 | F30: 0.8 | I30: BOLSA | J30: 100 | L30: 0.35 | M30: 0.5 | N30: 0.8
A31: HILO | B31: 500 | D31: =B34*1.45 -> 12.575125 | E31: =B34*1.75 -> 15.176875 | F31: =B34*1.99 -> 17.258275 | I31: HILO | J31: 350 | L31: =J34*1.4 -> 15.713158 | M31: =J34*1.75 -> 19.641447 | N31: =J34*1.99 -> 22.335132
A32: MARQUILLA | B32: 100 | I32: MARQUILLA | J32: 500
A33: GASTOS OPERATIVOS | B33: 2000 | I33: GASTOS OPERATIVOS | J33: 4000
B34: =SUM(B20:B33)/F20 -> 8.6725 | J34: =SUM(J20:J33)/N20 -> 11.223684
A36: CORTA VIENTO con Gorro CABALLERO | D36: SUBLIMACION TOTAL | I36: CORTA VIENTO CABALLERO | K36: DELANTERO Y TRASERO SUBLIMADO MANGAS Y GORRO UNICOLOR
A37: TELA MEMORY | B37: =2*1.7*F3 -> 12920 | I37: TELA MEMORY | J37: =2*2*N3 -> 15200
A38: SUBLIMACION | B38: =2*11000 -> 22000 | I38: SUBLIMACION | J38: 0
A39: CORTE | B39: 700 | I39: CORTE | J39: 700
