Workbook

Sheet Presupuesto
B2: PRESUPUESTO | K2: calculadora
O3: Código
B4: Número | C4: PRE-0001 | D4: Fecha | K4: Producto | O4: =IFERROR(INDEX(Productos!$B$3:$B$500,MATCH($L$4,Productos!$C$3:$C$500,0)),"")
B5: Cliente | K5: Talla | O5: =IFERROR(INDEX(Productos!$I$3:$I$100,MATCH($L$5,Productos!$J$3:$J$100,0)),"")
B6: Teléfono | K6: Tela (si aplica) | O6: =IFERROR(INDEX(Materiales!$B$3:$B$500,MATCH($L$6,Materiales!$C$3:$C$500,0)),"")
B7: Moneda a mostrar | C7: USD | K7: Técnica | O7: =IFERROR(INDEX(Produccion!$I$3:$I$100,MATCH($L$7,Produccion!$J$3:$J$100,0)),"")
B8: Estado | C8: Aceptado | K8: Volumen | O8: =IFERROR(INDEX(Produccion!$T$3:$T$100,MATCH($L$8,Produccion!$U$3:$U$100,0)),"")
B9: ITEM | C9: CANT | D9: DESCRIPCIÓN | E9: COSTO UNIT | F9: TOTAL | G9: Auxiliar | K9: Cantidad | L9: 1
K11: Resultado
K12: Consumo tela (m²) | L12: =IFERROR(INDEX(Produccion!$AM$3:$AM$57,MATCH($O$4&"|"&$O$5,Produccion!$AO$3:$AO$57,0)),"Sin dato") -> Sin dato
K13: Costo unitario tela (USD) | L13: =IFERROR(INDEX(Materiales!$E$3:$E$58,MATCH($O$6,Materiales!$B$3:$B$58,0))/IF(INDEX(Materiales!$G$3:$G$58,MATCH($O$6,Materiales!$B$3:$B$58,0))="Cop",TasasCambio!$C$4,1),0) -> 0
K14: Costo tela (USD) | L14: =IF(ISNUMBER($L$12),$L$12*$L$13,0) -> 0
K15: Costo actividades (USD) | L15: =SUMPRODUCT((Produccion!$AE$3:$AE$451=$O$4)*(Produccion!$AF$3:$AF$451=$O$8)*(Produccion!$AI$3:$AI$451)*(Produccion!$AG$3:$AG$451)*((Produccion!$AH$3:$AH$451="Cop")*(1/TasasCambio!$C$4)+(Produccion!$AH$3:$AH$451="Usd")*1)) -> 0
K16: Costo total unitario (USD) | L16: =$L$14+$L$15 -> 0
K17: Precio unitario en moneda mostrada | L17: =$L$16*INDEX(TasasCambio!$C$3:$C$5,MATCH($C$7,TasasCambio!$B$3:$B$5,0)) -> 0
D24: TOTAL A PAGAR | F24: =SUM(T_Items[TOTAL]) -> 0
E25: ABONO:
E26: RESTA: | F26: =F24-F25 -> 0 | K26: Editando línea:
B28: Buscar: | K28: Botones (asignar tras importar el macro): ① Agregar/Actualizar → M01_GestionPresupuesto.AgregarOActualizarItem ② Cargar para editar → M01_GestionPresupuesto.CargarItemParaEditar ③ Limpiar → M01_GestionPresupuesto.LimpiarConfigurador ④ Eliminar → M01_GestionPresupuesto.EliminarItem ⑤ Aceptar Presupuesto → M01_GestionPresupuesto.AceptarPresupuesto ⑥ Cargar Comanda → M01_GestionPresupuesto.CargarComanda ⑦ Actualizar Tasas → M01_GestionPresupuesto.ActualizarTasas
B29: Elige un presupuesto ya aceptado y usa el botón Cargar Comanda para reabrirlo.
B31: Tasas de Cambio
B32: COP por USD | C32: 3400
B33: VES por USD | C33: 950
B34: Cambia el valor y usa el botón Actualizar Tasas para guardarlo.
K36: Nota: el costo de actividades usa solo fact_costo_actividad_producto (materiales que la técnica también dispara, ej. Etiquetas por Sublimado, no se suman aparte todavía).

Sheet Productos
B2: Codigo_Producto | C2: Nombre | D2: Categoría | E2: Subcategoría | I2: Id_talla | J2: Talla | L2: Id_Segmento | M2: descripción | O2: id_variante | P2: descripción
B3: P-01 | C3: Bandanas | D3: Accesorios | E3: Promocionales | I3: Tall-01 | J3: Niño | L3: Dis-01 | M3: Corporativo | O3: VAR001 | P3: Básico
B4: P-02 | C4: Bolsas Ecológicas | D4: Accesorios | E4: Promocionales | I4: Tall-02 | J4: Dama | L4: Dis-02 | M4: Deportivo | O4: VAR002 | P4: Botones + ojales
B5: P-03 | C5: Buzos | D5: Ropa Casual | E5: Chaquetas | I5: Tall-03 | J5: Caballero | L5: Dis-03 | M5: Personalizado | O5: VAR003 | P5: Broches
B6: P-04 | C6: Camisa | D6: Ropa Formal | E6: Camisas | I6: Tall-04 | J6: Plus | L6: Dis-04 | M6: Unicolor | O6: VAR004 | P6: Con bolsillos
B7: P-05 | C7: Chaleco | D7: Ropa Deportiva | E7: Chalecos | I7: Tall-05 | J7: Unica | O7: VAR005 | P7: Con cuello y botones
B8: P-06 | C8: Chaqueta | D8: Ropa Deportiva | E8: Chaquetas | I8: Tall-06 | J8: Accesorio | O8: VAR006 | P8: Con gorro
B9: P-07 | C9: Chemis | D9: Ropa Casual | E9: Camisetas | O9: VAR007 | P9: Cuello camisa
B10: P-08 | C10: Cortavientos | D10: Ropa Deportiva | E10: Chaquetas | O10: VAR008 | P10: Cuello Chemise
B11: P-09 | C11: Delantales | D11: Ropa Laboral | E11: Uniformes | O11: VAR009 | P11: Cuello en V
B12: P-10 | C12: Franelas | D12: Ropa Deportiva | E12: Franelas | O12: VAR010 | P12: Cuello Mao
B13: P-11 | C13: Franelillas | D13: Ropa Casual | E13: Camisetas | O13: VAR011 | P13: Cuello Y Puños
B14: P-12 | C14: Genérico (todos) | D14: Genérico | E14: Genérico | O14: VAR012 | P14: Manga corta
B15: P-13 | C15: Gorras | D15: Accesorios | E15: Deportivos | O15: VAR013 | P15: Manga larga
B16: P-14 | C16: Hoodies | D16: Ropa Casual | E16: Suéteres | O16: VAR014 | P16: Sin mangas
B17: P-15 | C17: Shorts | D17: Ropa Deportiva | E17: Pantalones | O17: VAR015 | P17: Unicolor
B18: P-16 | C18: Tazas | D18: Accesorios | E18: Hogar
B19: P-17 | C19: Uniformes | D19: Ropa Laboral | E19: Uniformes
B20: P-18 | C20: Viseras | D20: Accesorios | E20: Deportivos
B21: P-19 | C21: Bolsa de arena | D21: Accesorios | E21: -
B22: P-20 | C22: Chemis con uniones telas | D22: Ropa Casual | E22: Camisetas
B23: P-21 | C23: Cojines | D23: Accesorios | E23: Hogar
B24: P-22 | C24: Falda short | D24: Ropa Casual | E24: Faldas
B25: P-23 | C25: Funda porta canillera S/C | D25: Accesorios | E25: -
B26: P-24 | C26: Licra | D26: Tela | E26: -
B27: P-25 | C27: Mono | D27: Ropa Deportiva | E27: Mono
B28: P-26 | C28: Porta canilleras c/ corte | D28: Accesorios | E28: -
B29: P-27 | C29: Protectores arqueros | D29: Accesorios | E29: -
... B41: P-39 | C41: Mousepad | D41: Accesorios | E41: Tecnología

Sheet Materiales
B2: ID_Material | C2: Nombre_Material | D2: Color_Material | E2: Costo_Unitario_Detal | F2: Costo_Unitario_Mayor | G2: Moneda | H2: Proveedor | I2: Stock_Minimo | J2: Ubicación Actual | K2: Entradas | L2: Salidas | M2: Stock_Actual2 | N2: Valor_Stock | O2: EsTela
B3: Mat-01 | C3: Bolsa | E3: 100 | G3: Cop | H3: Proveedor M | O3: =IF(ISNUMBER(SEARCH("Tela",C3)),C3,"")
B4: Mat-02 | C4: Botones + ojales | E4: 4000 | G4: Cop | H4: Proveedor J | O4: =IF(ISNUMBER(SEARCH("Tela",C4)),C4,"")
B5: Mat-03 | C5: Broches | E5: 1500 | G5: Cop | O5: =IF(ISNUMBER(SEARCH("Tela",C5)),C5,"")
B6: Mat-04 | C6: cierre diente de perro | E6: 1800 | G6: Cop | O6: =IF(ISNUMBER(SEARCH("Tela",C6)),C6,"")
B7: Mat-05 | C7: Cierre Naylon | E7: 1300 | G7: Cop | H7: Proveedor I | O7: =IF(ISNUMBER(SEARCH("Tela",C7)),C7,"")
B8: Mat-06 | C8: cierre reflectivo | E8: 6000 | G8: Cop | O8: =IF(ISNUMBER(SEARCH("Tela",C8)),C8,"")
B9: Mat-07 | C9: Cordon | E9: 1400 | G9: Cop | H9: Proveedor N | O9: =IF(ISNUMBER(SEARCH("Tela",C9)),C9,"")
B10: Mat-08 | C10: Etiquetas | E10: 250 | G10: Cop | H10: Proveedor K | O10: =IF(ISNUMBER(SEARCH("Tela",C10)),C10,"")
B11: Mat-09 | C11: Hilo | E11: 250 | G11: Cop | H11: Proveedor H | O11: =IF(ISNUMBER(SEARCH("Tela",C11)),C11,"")
B12: Mat-10 | C12: Marquilla | E12: 120 | G12: Cop | H12: Proveedor N | O12: =IF(ISNUMBER(SEARCH("Tela",C12)),C12,"")
B13: Mat-11 | C13: Tela Algodón | E13: 4.4 | G13: Usd | H13: Portofino- Cucuta | O13: =IF(ISNUMBER(SEARCH("Tela",C13)),C13,"") -> Tela Algodón
B14: Mat-12 | C14: Tela Algodón egipcio | E14: 3.9 | G14: Usd | H14: Castillo | O14: =IF(ISNUMBER(SEARCH("Tela",C14)),C14,"") -> Tela Algodón egipcio
B15: Mat-13 | C15: Tela Atlética | E15: 2.3 | F15: 1.8 | G15: Usd | H15: Castillo | O15: =IF(ISNUMBER(SEARCH("Tela",C15)),C15,"") -> Tela Atlética
B16: Mat-14 | C16: Tela Columbia | G16: Usd | O16: =IF(ISNUMBER(SEARCH("Tela",C16)),C16,"") -> Tela Columbia
B17: Mat-15 | C17: Tela Dri Fit | E17: 2.5 | F17: 1.95 | G17: Usd | O17: =IF(ISNUMBER(SEARCH("Tela",C17)),C17,"") -> Tela Dri Fit
B18: Mat-16 | C18: Tela Drill sahara | E18: 3.7 | G18: Usd | O18: =IF(ISNUMBER(SEARCH("Tela",C18)),C18,"") -> Tela Drill sahara
B19: Mat-17 | C19: Tela fashion mix spt | E19: 1.5 | G19: Usd | O19: =IF(ISNUMBER(SEARCH("Tela",C19)),C19,"") -> Tela fashion mix spt
B20: Mat-18 | C20: Tela Gabardina | E20: 3.5 | G20: Usd | O20: =IF(ISNUMBER(SEARCH("Tela",C20)),C20,"") -> Tela Gabardina
B21: Mat-19 | C21: Tela LaCoste | E21: 4 | G21: Usd | H21: Kilometro - cucuta | O21: =IF(ISNUMBER(SEARCH("Tela",C21)),C21,"") -> Tela LaCoste
B22: Mat-20 | C22: Tela Licra careoca | E22: 5.95 | G22: Usd | O22: =IF(ISNUMBER(SEARCH("Tela",C22)),C22,"") -> Tela Licra careoca
B23: Mat-21 | C23: Tela Licra eternity | E23: 3.8 | G23: Usd | O23: =IF(ISNUMBER(SEARCH("Tela",C23)),C23,"") -> Tela Licra eternity
B24: Mat-22 | C24: Tela Licra super leggyn | E24: 2.5 | G24: Usd | H24: Proveedor C | O24: =IF(ISNUMBER(SEARCH("Tela",C24)),C24,"") -> Tela Licra super leggyn
B25: Mat-23 | C25: Tela Licra super pacyfic | E25: 5.8 | G25: Usd | O25: =IF(ISNUMBER(SEARCH("Tela",C25)),C25,"") -> Tela Licra super pacyfic
B26: Mat-24 | C26: Tela Malla forro | E26: 1.5 | G26: Usd | O26: =IF(ISNUMBER(SEARCH("Tela",C26)),C26,"") -> Tela Malla forro
B27: Mat-25 | C27: Tela malla maraton | E27: 2 | G27: Usd | O27: =IF(ISNUMBER(SEARCH("Tela",C27)),C27,"") -> Tela malla maraton
B28: Mat-26 | C28: Tela Memory | E28: 1.5 | G28: Usd | H28: Proveedor G | O28: =IF(ISNUMBER(SEARCH("Tela",C28)),C28,"") -> Tela Memory
B29: Mat-27 | C29: Tela Micro perforada | G29: Usd | O29: =IF(ISNUMBER(SEARCH("Tela",C29)),C29,"") -> Tela Micro perforada
B30: Mat-28 | C30: Tela Microdurasno | E30: 2.5 | G30: Usd | O30: =IF(ISNUMBER(SEARCH("Tela",C30)),C30,"") -> Tela Microdurasno
B31: Mat-29 | C31: Tela Microfibra mundial | E31: 1.95 | G31: Usd | O31: =IF(ISNUMBER(SEARCH("Tela",C31)),C31,"") -> Tela Microfibra mundial
B32: Mat-30 | C32: Tela Mono | E32: 3.9 | G32: Usd | H32: Proveedor E | O32: =IF(ISNUMBER(SEARCH("Tela",C32)),C32,"") -> Tela Mono
B33: Mat-31 | C33: Tela Mono hollister | E33: 4.9 | G33: Usd | O33: =IF(ISNUMBER(SEARCH("Tela",C33)),C33,"") -> Tela Mono hollister
B34: Mat-32 | C34: Tela Muselina | E34: 2.3 | F34: 1.2 | G34: Usd | H34: Proveedor A | O34: =IF(ISNUMBER(SEARCH("Tela",C34)),C34,"") -> Tela Muselina
B35: Mat-33 | C35: Tela neopreno | E35: 7.5 | G35: Usd | O35: =IF(ISNUMBER(SEARCH("Tela",C35)),C35,"") -> Tela neopreno
B36: Mat-34 | C36: Tela North face | E36: 5.5 | F36: 4 | G36: Usd | O36: =IF(ISNUMBER(SEARCH("Tela",C36)),C36,"") -> Tela North face
B37: Mat-35 | C37: Tela Oxford | E37: 4 | G37: Usd | O37: =IF(ISNUMBER(SEARCH("Tela",C37)),C37,"") -> Tela Oxford
B38: Mat-36 | C38: Tela Piqué armani | E38: 2.95 | G38: Usd | O38: =IF(ISNUMBER(SEARCH("Tela",C38)),C38,"") -> Tela Piqué armani
B39: Mat-37 | C39: Tela polar | E39: 3.5 | G39: Usd | O39: =IF(ISNUMBER(SEARCH("Tela",C39)),C39,"") -> Tela polar
B40: Mat-38 | C40: Tela polo wafy | E40: 2.5 | G40: Usd | O40: =IF(ISNUMBER(SEARCH("Tela",C40)),C40,"") -> Tela polo wafy
B41: Mat-39 | C41: Tela qatar | F41: 1.2 | G41: Usd | O41: =IF(ISNUMBER(SEARCH("Tela",C41)),C41,"") -> Tela qatar
...

Sheet Produccion
B2: ID_Actividad | C2: Nombre_Actividad | D2: Tipo | E2: Unidad | F2: Descripción | I2: Id_Tecnica | J2: técnica | K2: descripción | N2: Id_Tamano | O2: Id_Tecnica | P2: Nombre_Tamano | Q2: Ancho_cm | R2: Alto_cm | T2: id_tipo_precio | U2: Volumen_Compra | W2: Técnica base | X2: Actividad relacionada | Y2: Observación | Z2: Id_Actividad_Resuelto | AA2: Id_Material_Resuelto | AC2: id_costo | AD2: id_actividad | AE2: Codigo_Producto | AF2: id_tipo_precio | AG2: costo_unitario | AH2: Moneda_Act | AK2: Codigo_Producto | AL2: Talla | AM2: Cantidad_Tela_m² | AN2: Cantidad_Tela_Formula
B3: Act-01 | C3: Corte del Plotter | D3: Operación | I3: Tec-01 | J3: VINIL | N3: TAM-01 | O3: Tec-01 | P3: Vinil 15 cm | Q3: 15 | R3: 15 | T3: VC001 | U3: Detal | W3: BORDADO | X3: BORDADO | Z3: Act-02 | AC3: CTS0028 | AD3: Act-09 | AE3: P-02 | AF3: VC001 | AG3: 1500 | AH3: Cop | AI3: =IF(COUNTIFS($W$3:$W$25,Presupuesto!$L$7,$Z$3:$Z$25,AD3)>0,1,0) -> 0 | AK3: P-01 | AL3: Tall-06 | AM3: 0.1625 | AO3: =AK3&"|"&AL3 -> P-01|Tall-06
B4: Act-02 | C4: Bordado | D4: Operación | E4: unidad | I4: Tec-02 | J4: SUBLIMADO | N4: TAM-02 | O4: Tec-01 | P4: Vinil Carta | Q4: 21.59 | R4: 27.94 | T4: VC002 | U4: Docena +12 | W4: BORDADO | X4: DIGITALIZACION | Z4: Act-07 | AC4: CTS0029 | AD4: Act-09 | AE4: P-02 | AF4: VC002 | AG4: 1300 | AH4: Cop | AI4: =IF(COUNTIFS($W$3:$W$25,Presupuesto!$L$7,$Z$3:$Z$25,AD4)>0,1,0) -> 0 | AK4: P-02 | AL4: Tall-06 | AO4: =AK4&"|"&AL4 -> P-02|Tall-06
B5: Act-03 | C5: Depilada | D5: Operación | I5: Tec-03 | J5: DTF | N5: TAM-03 | O5: Tec-01 | P5: Vinil Oficio | Q5: 21.59 | R5: 33.02 | T5: VC003 | U5: Mayor +1000 | W5: DTF | X5: DTF | Z5: Act-12 | AC5: CTS0030 | AD5: Act-09 | AE5: P-02 | AF5: VC003 | AG5: 1100 | AH5: Cop | AI5: =IF(COUNTIFS($W$3:$W$25,Presupuesto!$L$7,$Z$3:$Z$25,AD5)>0,1,0) -> 0 | AK5: P-03 | AL5: Tall-01 | AM5: 0.7 | AO5: =AK5&"|"&AL5 -> P-03|Tall-01
B6: Act-04 | C6: Diseño | D6: Operación | I6: Tec-04 | J6: VINIL + SUBLIMADO | N6: TAM-04 | O6: Tec-01 | P6: Vinil 20x20 cm | Q6: 20 | R6: 20 | W6: DTF | X6: diseño | Z6: Act-04 | AC6: CTS0031 | AD6: Act-09 | AE6: P-03 | AF6: VC001 | AG6: 3500 | AH6: Cop | AI6: =IF(COUNTIFS($W$3:$W$25,Presupuesto!$L$7,$Z$3:$Z$25,AD6)>0,1,0) -> 0 | AK6: P-03 | AL6: Tall-02 | AM6: 0.9 | AO6: =AK6&"|"&AL6 -> P-03|Tall-02
B7: Act-05 | C7: Colocación cierres | D7: Operación | E7: unidad | I7: Tec-05 | J7: BORDADO | N7: TAM-05 | O7: Tec-01 | P7: Vinil 25x30 cm | Q7: 25 | R7: 30 | W7: DTF | X7: Planchado Grande | Z7: Act-17 | AC7: CTS0032 | AD7: Act-09 | AE7: P-03 | AF7: VC002 | AG7: 2500 | AH7: Cop | AI7: =IF(COUNTIFS($W$3:$W$25,Presupuesto!$L$7,$Z$3:$Z$25,AD7)>0,1,0) -> 0 | AK7: P-03 | AL7: Tall-03 | AM7: 2 | AO7: =AK7&"|"&AL7 -> P-03|Tall-03
B8: Act-06 | C8: Confección bolsillos | D8: Operación | E8: unidad | N8: TAM-06 | O8: Tec-02 | P8: Sublimado Carta | Q8: 21.59 | R8: 27.94 | W8: SUBLIMADO | X8: Sublimación | Y8: - | Z8: Act-10 | AC8: CTS0033 | AD8: Act-09 | AE8: P-05 | AF8: VC001 | AG8: 4000 | AH8: Cop | AI8: =IF(COUNTIFS($W$3:$W$25,Presupuesto!$L$7,$Z$3:$Z$25,AD8)>0,1,0) -> 0 | AK8: P-04 | AL8: Tall-01 | AO8: =AK8&"|"&AL8 -> P-04|Tall-01
B9: Act-07 | C9: Digitalizacion | D9: Operación | N9: TAM-07 | O9: Tec-02 | P9: Sublimado Oficio | Q9: 21.59 | R9: 33.02 | W9: SUBLIMADO | X9: Diseño | Y9: - | Z9: Act-04 | AC9: CTS0034 | AD9: Act-09 | AE9: P-05 | AF9: VC002 | AG9: 3500 | AH9: Cop | AI9: =IF(COUNTIFS($W$3:$W$25,Presupuesto!$L$7,$Z$3:$Z$25,AD9)>0,1,0) -> 0 | AK9: P-04 | AL9: Tall-02 | AO9: =AK9&"|"&AL9 -> P-04|Tall-02
B10: Act-08 | C10: Corte de Tela | D10: Operación | E10: unidad | N10: TAM-08 | O10: Tec-02 | P10: Sublimado Delantero | W10: SUBLIMADO | X10: Etiquetas | Y10: - | AA10: Mat-08 | AC10: CTS0035 | AD10: Act-09 | AE10: P-05 | AF10: VC003 | AG10: 3000 | AH10: Cop | AI10: =IF(COUNTIFS($W$3:$W$25,Presupuesto!$L$7,$Z$3:$Z$25,AD10)>0,1,0) -> 0 | AK10: P-04 | AL10: Tall-03 | AM10: 1.6 | AO10: =AK10&"|"&AL10 -> P-04|Tall-03
B11: Act-09 | C11: Costura | D11: Operación | E11: unidad | N11: TAM-09 | O11: Tec-02 | P11: Sublimado Total | W11: SUBLIMADO | X11: Planchado Grande | Y11: - | Z11: Act-17 | AC11: CTS0036 | AD11: Act-09 | AE11: P-06 | AF11: VC001 | AG11: 6000 | AH11: Cop | AI11: =IF(COUNTIFS($W$3:$W$25,Presupuesto!$L$7,$Z$3:$Z$25,AD11)>0,1,0) -> 0 | AK11: P-05 | AL11: Tall-01 | AO11: =AK11&"|"&AL11 -> P-05|Tall-01
B12: Act-10 | C12: Sublimación | D12: Operación | E12: m² | W12: VINIL | X12: Vinilado | Y12: Según tamaño | Z12: Act-11 | AC12: CTS0037 | AD12: Act-09 | AE12: P-06 | AF12: VC002 | AG12: 5500 | AH12: Cop | AI12: =IF(COUNTIFS($W$3:$W$25,Presupuesto!$L$7,$Z$3:$Z$25,AD12)>0,1,0) -> 0 | AK12: P-05 | AL12: Tall-02 | AO12: =AK12&"|"&AL12 -> P-05|Tall-02
B13: Act-11 | C13: Vinilado | D13: Operación | E13: m² | W13: VINIL | X13: Corte del Plotter | Y13: - | Z13: Act-01 | AC13: CTS0038 | AD13: Act-09 | AE13: P-06 | AF13: VC003 | AG13: 5000 | AH13: Cop | AI13: =IF(COUNTIFS($W$3:$W$25,Presupuesto!$L$7,$Z$3:$Z$25,AD13)>0,1,0) -> 0 | AK13: P-05 | AL13: Tall-03 | AO13: =AK13&"|"&AL13 -> P-05|Tall-03
B14: Act-21 | C14: Gastos Operativos | D14: Operación | E14: unidad | W14: VINIL | X14: Depilada | Y14: - | Z14: Act-03 | AC14: CTS0039 | AD14: Act-09 | AE14: P-07 | AF14: VC001 | AG14: 5000 | AH14: Cop | AI14: =IF(COUNTIFS($W$3:$W$25,Presupuesto!$L$7,$Z$3:$Z$25,AD14)>0,1,0) -> 0 | AK14: P-06 | AL14: Tall-01 | AO14: =AK14&"|"&AL14 -> P-06|Tall-01
B15: Act-13 | C15: Corte de papel | D15: Operación | E15: unidad | W15: VINIL | X15: Etiquetas | Y15: - | AA15: Mat-08 | AC15: CTS0040 | AD15: Act-09 | AE15: P-07 | AF15: VC002 | AG15: 4000 | AH15: Cop | AI15: =IF(COUNTIFS($W$3:$W$25,Presupuesto!$L$7,$Z$3:$Z$25,AD15)>0,1,0) -> 0 | AK15: P-06 | AL15: Tall-02 | AO15: =AK15&"|"&AL15 -> P-06|Tall-02
B16: Act-16 | C16: Planchado pequeño | D16: Operación | E16: unidad | W16: VINIL | X16: Planchado Grande | Y16: - | Z16: Act-17 | AC16: CTS0041 | AD16: Act-09 | AE16: P-07 | AF16: VC003 | AG16: 2500 | AH16: Cop | AI16: =IF(COUNTIFS($W$3:$W$25,Presupuesto!$L$7,$Z$3:$Z$25,AD16)>0,1,0) -> 0 | AK16: P-06 | AL16: Tall-03 | AM16: 2 | AO16: =AK16&"|"&AL16 -> P-06|Tall-03
B17: Act-17 | C17: Planchado Grande | D17: Operación | E17: unidad | W17: VINIL | X17: Diseño | Z17: Act-04 | AC17: CTS0086 | AD17: Act-09 | AE17: P-08 | AF17: VC001 | AG17: 6000 | AH17: Cop | AI17: =IF(COUNTIFS($W$3:$W$25,Presupuesto!$L$7,$Z$3:$Z$25,AD17)>0,1,0) -> 0 | AK17: P-07 | AL17: Tall-01 | AM17: 0.6 | AO17: =AK17&"|"&AL17 -> P-07|Tall-01
B18: Act-27 | C18: Terminacion | D18: Operación | E18: unidad | W18: VINIL + SUBLIMADO | X18: Sublimación | Y18: Tamaño específico | Z18: Act-10 | AC18: CTS0042 | AD18: Act-09 | AE18: P-10 | AF18: VC001 | AG18: 3000 | AH18: Cop | AI18: =IF(COUNTIFS($W$3:$W$25,Presupuesto!$L$7,$Z$3:$Z$25,AD18)>0,1,0) -> 0 | AK18: P-07 | AL18: Tall-02 | AM18: 0.8 | AO18: =AK18&"|"&AL18 -> P-07|Tall-02
B19: Act-18 | C19: Impresión | D19: Operación | E19: m² | W19: VINIL + SUBLIMADO | X19: Vinilado | Y19: Tamaño específico | Z19: Act-11 | AC19: CTS0043 | AD19: Act-09 | AE19: P-10 | AF19: VC002 | AG19: 2000 | AH19: Cop | AI19: =IF(COUNTIFS($W$3:$W$25,Presupuesto!$L$7,$Z$3:$Z$25,AD19)>0,1,0) -> 0 | AK19: P-07 | AL19: Tall-03 | AM19: 1 | AO19: =AK19&"|"&AL19 -> P-07|Tall-03
B20: Act-12 | C20: DTF | D20: Operación | E20: m² | W20: VINIL + SUBLIMADO | X20: Corte del Plotter | Z20: Act-01 | AC20: CTS0044 | AD20: Act-09 | AE20: P-10 | AF20: VC003 | AG20: 1600 | AH20: Cop | AI20: =IF(COUNTIFS($W$3:$W$25,Presupuesto!$L$7,$Z$3:$Z$25,AD20)>0,1,0) -> 0 | AK20: P-08 | AL20: Tall-01 | AM20: 1.4 | AO20: =AK20&"|"&AL20 -> P-08|Tall-01
W21: VINIL + SUBLIMADO | X21: Depilada | Z21: Act-03 | AC21: CTS0013 | AD21: Act-01 | AE21: P-12 | AF21: VC001 | AG21: 200 | AH21: Cop | AI21: =IF(COUNTIFS($W$3:$W$25,Presupuesto!$L$7,$Z$3:$Z$25,AD21)>0,1,0) -> 0 | AK21: P-08 | AL21: Tall-02 | AM21: 1.8 | AO21: =AK21&"|"&AL21 -> P-08|Tall-02
W22: VINIL + SUBLIMADO | X22: diseño | Y22: - | Z22: Act-04 | AC22: CTS0014 | AD22: Act-01 | AE22: P-12 | AF22: VC002 | AG22: 200 | AH22: Cop | AI22: =IF(COUNTIFS($W$3:$W$25,Presupuesto!$L$7,$Z$3:$Z$25,AD22)>0,1,0) -> 0 | AK22: P-08 | AL22: Tall-03 | AM22: 2.2 | AO22: =AK22&"|"&AL22 -> P-08|Tall-03
W23: VINIL + SUBLIMADO | X23: Etiquetas | Y23: - | AA23: Mat-08 | AC23: CTS0015 | AD23: Act-01 | AE23: P-12 | AF23: VC003 | AG23: 200 | AH23: Cop | AI23: =IF(COUNTIFS($W$3:$W$25,Presupuesto!$L$7,$Z$3:$Z$25,AD23)>0,1,0) -> 0 | AK23: P-09 | AL23: Tall-06 | AM23: 0.7 | AO23: =AK23&"|"&AL23 -> P-09|Tall-06
W24: VINIL + SUBLIMADO | X24: Planchado Grande | Z24: Act-17 | AC24: CTS0016 | AD24: Act-03 | AE24: P-12 | AF24: VC001 | AG24: 500 | AH24: Cop | AI24: =IF(COUNTIFS($W$3:$W$25,Presupuesto!$L$7,$Z$3:$Z$25,AD24)>0,1,0) -> 0 | AK24: P-10 | AL24: Tall-01 | AM24: 0.6 | AO24: =AK24&"|"&AL24 -> P-10|Tall-01
W25: VINIL + SUBLIMADO | X25: Planchado Grande | Z25: Act-17 | AC25: CTS0017 | AD25: Act-03 | AE25: P-12 | AF25: VC002 | AG25: 400 | AH25: Cop | AI25: =IF(COUNTIFS($W$3:$W$25,Presupuesto!$L$7,$Z$3:$Z$25,AD25)>0,1,0) -> 0 | AK25: P-10 | AL25: Tall-02 | AM25: 0.8 | AO25: =AK25&"|"&AL25 -> P-10|Tall-02
AC26: CTS0018 | AD26: Act-03 | AE26: P-12 | AF26: VC003 | AG26: 200 | AH26: Cop | AI26: =IF(COUNTIFS($W$3:$W$25,Presupuesto!$L$7,$Z$3:$Z$25,AD26)>0,1,0) -> 0 | AK26: P-10 | AL26: Tall-03 | AM26: 1.1 | AO26: =AK26&"|"&AL26 -> P-10|Tall-03
W27: Completado con RECETAS_NORMALIZADAS.xlsx: +363 filas de costo por actividad, +6 filas de consumo de tela. Filas nuevas usan codigo CTSX#### para no chocar con las reales (CTS####). | AC27: CTS0010 | AD27: Act-04 | AE27: P-12 | AF27: VC001 | AG27: 3000 | AH27: Cop | AI27: =IF(COUNTIFS($W$3:$W$25,Presupuesto!$L$7,$Z$3:$Z$25,AD27)>0,1,0) -> 0 | AK27: P-10 | AL27: Tall-04 | AM27: 1.2 | AO27: =AK27&"|"&AL27 -> P-10|Tall-04
AC28: CTS0011 | AD28: Act-04 | AE28: P-12 | AF28: VC002 | AG28: 2000 | AH28: Cop | AI28: =IF(COUNTIFS($W$3:$W$25,Presupuesto!$L$7,$Z$3:$Z$25,AD28)>0,1,0) -> 0 | AK28: P-11 | AL28: Tall-01 | AM28: 0.33333333 | AO28: =AK28&"|"&AL28 -> P-11|Tall-01
AC29: CTS0012 | AD29: Act-04 | AE29: P-12 | AF29: VC003 | AG29: 1500 | AH29: Cop | AI29: =IF(COUNTIFS($W$3:$W$25,Presupuesto!$L$7,$Z$3:$Z$25,AD29)>0,1,0) -> 0 | AK29: P-11 | AL29: Tall-02 | AM29: 0.46666667 | AO29: =AK29&"|"&AL29 -> P-11|Tall-02
AC30: CTS0001 | AD30: Act-08 | AE30: P-12 | AF30: VC001 | AG30: 700 | AH30: Cop | AI30: =IF(COUNTIFS($W$3:$W$25,Presupuesto!$L$7,$Z$3:$Z$25,AD30)>0,1,0) -> 0 | AK30: P-11 | AL30: Tall-03 | AM30: 0.53333333 | AO30: =AK30&"|"&AL30 -> P-11|Tall-03
AC31: CTS0002 | AD31: Act-08 | AE31: P-12 | AF31: VC002 | AG31: 500 | AH31: Cop | AI31: =IF(COUNTIFS($W$3:$W$25,Presupuesto!$L$7,$Z$3:$Z$25,AD31)>0,1,0) -> 0 | AK31: P-14 | AL31: Tall-01 | AM31: 1.5 | AO31: =AK31&"|"&AL31 -> P-14|Tall-01
AC32: CTS0003 | AD32: Act-08 | AE32: P-12 | AF32: VC003 | AG32: 350 | AH32: Cop | AI32: =IF(COUNTIFS($W$3:$W$25,Presupuesto!$L$7,$Z$3:$Z$25,AD32)>0,1,0) -> 0 | AK32: P-14 | AL32: Tall-02 | AM32: 1.7 | AO32: =AK32&"|"&AL32 -> P-14|Tall-02
AC33: CTS0045 | AD33: Act-09 | AE33: P-12 | AF33: VC001 | AG33: 1000 | AH33: Cop | AI33: =IF(COUNTIFS($W$3:$W$25,Presupuesto!$L$7,$Z$3:$Z$25,AD33)>0,1,0) -> 0 | AK33: P-14 | AL33: Tall-03 | AM33: 2 | AO33: =AK33&"|"&AL33 -> P-14|Tall-03
AC34: CTS0046 | AD34: Act-09 | AE34: P-12 | AF34: VC002 | AG34: 900 | AH34: Cop | AI34: =IF(COUNTIFS($W$3:$W$25,Presupuesto!$L$7,$Z$3:$Z$25,AD34)>0,1,0) -> 0 | AK34: P-15 | AL34: Tall-01 | AM34: 0.275 | AO34: =AK34&"|"&AL34 -> P-15|Tall-01
AC35: CTS0047 | AD35: Act-09 | AE35: P-12 | AF35: VC003 | AG35: 700 | AH35: Cop | AI35: =IF(COUNTIFS($W$3:$W$25,Presupuesto!$L$7,$Z$3:$Z$25,AD35)>0,1,0) -> 0 | AK35: P-15 | AL35: Tall-02 | AM35: 0.3 | AO35: =AK35&"|"&AL35 -> P-15|Tall-02
AC36: CTS0087 | AD36: Act-10 | AE36: P-12 | AF36: VC001 | AG36: 9500 | AH36: Cop | AI36: =IF(COUNTIFS($W$3:$W$25,Presupuesto!$L$7,$Z$3:$Z$25,AD36)>0,1,0) -> 0 | AK36: P-15 | AL36: Tall-03 | AM36: 0.8 | AO36: =AK36&"|"&AL36 -> P-15|Tall-03
AC37: CTS0088 | AD37: Act-10 | AE37: P-12 | AF37: VC002 | AG37: 9500 | AH37: Cop | AI37: =IF(COUNTIFS($W$3:$W$25,Presupuesto!$L$7,$Z$3:$Z$25,AD37)>0,1,0) -> 0 | AK37: P-17 | AL37: Tall-01 | AM37: 1.2 | AO37: =AK37&"|"&AL37 -> P-17|Tall-01
AC38: CTS0089 | AD38: Act-10 | AE38: P-12 | AF38: VC003 | AG38: 9500 | AH38: Cop | AI38: =IF(COUNTIFS($W$3:$W$25,Presupuesto!$L$7,$Z$3:$Z$25,AD38)>0,1,0) -> 0 | AK38: P-17 | AL38: Tall-02 | AO38: =AK38&"|"&AL38 -> P-17|Tall-02
AC39: CTS0019 | AD39: Act-21 | AE39: P-12 | AF39: VC001 | AG39: 5000 | AH39: Cop | AI39: =IF(COUNTIFS($W$3:$W$25,Presupuesto!$L$7,$Z$3:$Z$25,AD39)>0,1,0) -> 0 | AK39: P-17 | AL39: Tall-03 | AO39: =AK39&"|"&AL39 -> P-17|Tall-03
AC40: CTS0020 | AD40: Act-21 | AE40: P-12 | AF40: VC002 | AG40: 5000 | AH40: Cop | AI40: =IF(COUNTIFS($W$3:$W$25,Presupuesto!$L$7,$Z$3:$Z$25,AD40)>0,1,0) -> 0 | AK40: P-21 | AL40: Tall-06 | AM40: 0.58333333 | AO40: =AK40&"|"&AL40 -> P-21|Tall-06
AC41: CTS0021 | AD41: Act-21 | AE41: P-12 | AF41: VC003 | AG41: 5000 | AH41: Cop | AI41: =IF(COUNTIFS($W$3:$W$25,Presupuesto!$L$7,$Z$3:$Z$25,AD41)>0,1,0) -> 0 | AK41: P-22 | AL41: Tall-02 | AM41: 1.5 | AO41: =AK41&"|"&AL41 -> P-22|Tall-02
...

Sheet TasasCambio
B2: Moneda | C2: Tasa_vs_USD | D2: Nota
B3: USD | C3: 1 | D3: Moneda base del motor
B4: COP | C4: 3400 | D4: Editable — actualizar segun tasa del dia
B5: VES | C5: 950 | D5: Editable — actualizar segun tasa del dia

Sheet Comandas
B2: Numero | C2: Fecha | D2: Cliente | E2: Telefono | F2: Moneda | G2: Total | H2: Abono | I2: Resta | J2: Estado | K2: Etiqueta | M2: Numero | N2: Item | O2: Cantidad | P2: Descripcion | Q2: CostoUnit | R2: Total | S2: Auxiliar
K3: =IF($B3="","",$B3&" - "&$D3)
B4: PRE-0001 | F4: USD | G4: 0 | H4: 206800 | I4: -206800 | J4: Aceptado | M4: PRE-0001 | N4: 3 | O4: 10 | P4: Franelas | Dama | Tela Microdurasno | VINIL | Q4: 20680 | R4: 206800 | S4: Franelas|Dama|Tela Microdurasno|VINIL|Detal
B6: Se llenan automáticamente al usar 'Aceptar Presupuesto' desde la hoja Presupuesto. No editar a mano salvo corrección puntual.
